Workbook

Sheet Guide
A1: IFRS 17 risk adjustment: cost of capital method, step by step
A2: A learning workbook. All numbers are illustrative (Solvency II-style stresses), not any company's calibration.
A4: How the RA is built in this workbook
A5: 1. Inputs: assumptions for a term assurance group and an immediate annuity group, the stresses, the correlation matrix and the cost of capital.
A6: 2. Term and Annuity: per-policy BEL by backward recursion, on best-estimate and on each stressed basis. Capital for a risk at time t = in-force at t × (stressed BEL − best-estimate BEL), with the stress applied from t onwards.
A7: 3. Capital: combines the risks each year with the correlation matrix (diversified), compares with each group on its own (standalone), and allocates the diversified capital back to the groups two ways: Euler (by each risk's marginal contribution) and proportional to standalone capital. Euler can give a group a small negative share when its risk hedges the other group (see the term group near the end of its term).
A8: 4. RA: RA(t) = CoC × Capital(t) × v + v × RA(t+1). This is the PV of the cost of holding capital until the business runs off (IFRS 17 para 37, B86–B92).
A9: 5. Factor method: calibrates one factor per risk at t = 0 and rebuilds the RA from exposures only. Compare it with the full method to see the approximation error.
A10: 6. Confidence: the implied confidence level for the para 119 disclosure, in a one-year view and a run-off view. The gap between them is itself a lesson (see the note on that sheet).
A11: 7. Summary: the key results and checks in one place.
A13: Timing conventions
A14: Premiums and expenses at the start of the year; death claims and annuity payments at the end of the year; lapses at the end of the year after deaths. Flat discount rate.
... A26: 6. Add the Solvency II expense inflation stress (+1% a year) to both product sheets. Hint: it needs the stress to start at the valuation date.

Sheet Summary
A1: Summary
A3: Alternative cost of capital rate | B3: 0.0475 | C3: Solvency II rate from 2027; used in the last column below
B5: Term | C5: Annuity | D5: Total | E5: RA at alternative CoC
A6: BEL at t = 0 | B6: =Term!T6 -> -12996781 | C6: =Annuity!N6 -> 61049166 | D6: =B6+C6 -> 48052384
A7: Capital at t = 0 (standalone) | B7: =Capital!M6 -> 3468959 | C7: =Capital!N6 -> 3054434 | D7: =B7+C7 -> 6523393
A8: Capital at t = 0 (diversified, allocated) | B8: =Capital!U6 -> 2497051.1 | C8: =Capital!V6 -> 1879136.7 | D8: =Capital!L6 -> 4376187.8
A9: RA at t = 0 (standalone) | B9: =RA!E6 -> 2120324.1 | C9: =RA!F6 -> 3343105.4 | D9: =B9+C9 -> 5463429.5 | E9: =D9*$B$3/Inputs!$B$5 -> 4325215
A10: RA at t = 0 (diversified, allocated) | B10: =RA!C6 -> 1221599 | C10: =RA!D6 -> 2679071.8 | D10: =RA!B6 -> 3900670.8 | E10: =D10*$B$3/Inputs!$B$5 -> 3088031.1
A11: RA at t = 0 (diversified, proportional) | B11: =RA!J6 -> 1422131 | C11: =RA!K6 -> 2478539.8 | D11: =B11+C11 -> 3900670.8
A12: Diversification benefit on RA | B12: =IF(B9=0,0,1-B10/B9) -> 0.42386213 | C12: =IF(C9=0,0,1-C10/C9) -> 0.19862777 | D12: =IF(D9=0,0,1-D10/D9) -> 0.28603987
A13: RA as % of BEL (diversified) | B13: =IF(B6=0,0,B10/ABS(B6)) -> 0.093992425 | C13: =IF(C6=0,0,C10/C6) -> 0.04388384
A14: RA by factor method | D14: ='Factor method'!H9 -> 2704841.6
A15: Factor method error | D15: ='Factor method'!H11 -> -0.30657014
A16: Implied confidence level: run-off view | D16: =Confidence!F12 -> 0.77051734
A17: Implied confidence level: one-year view | D17: =Confidence!F5 -> 0.98916033
A18: Implied confidence level, factor method (run-off view) | D18: ='Confidence Factor method'!F12 -> 0.69620641
A19: Checks (all should be 0)
A20: Term BEL identity (Σ |error|) | D20: =SUMPRODUCT(ABS(Term!AB6:AB25)) -> 1.1795009e-12
A21: Euler allocation adds up (Σ |error|) | D21: =SUMPRODUCT(ABS(Capital!W6:W50)) -> 0
A22: Allocated RAs add up (Σ |error|) | D22: =SUMPRODUCT(ABS(RA!I6:I50)) -> 0
A24: Note: the term BEL is negative because future premiums exceed expected claims and expenses (a profitable group).

Sheet Inputs
A1: Inputs
A2: Amounts in EUR. Blue cells can be changed.
A4: General
A5: Cost of capital rate | B5: 0.06 | C5: Solvency II Art. 39 (falls to 4.75% from 2027)
A6: Discount rate (flat) | B6: 0.03 | C6: Simplified risk-free rate
A7: Mortality basis (Gompertz-Makeham)
A8: A | B8: 0.00022 | C8: q = 1 − exp(−(A + B × C^age))
A9: B | B9: 2.7e-06
A10: C | B10: 1.124
A12: Term assurance group
A13: Number of policies | B13: 10000
A14: Age at start | B14: 40
A15: Term (years) | B15: 20 | C15: Projection rows cover 20 years
A16: Sum assured per policy | B16: 200000
A17: Annual premium per policy | B17: 400 | C17: Paid at start of year
A18: Expense per policy, year 1 | B18: 60
A19: Expense inflation | B19: 0.03 | C19: Used for both groups
A20: Lapse rate | B20: 0.05
A21: Mortality multiplier | B21: 1 | C21: × base table
A23: Immediate annuity group
A24: Number of policies | B24: 300
A25: Age at start | B25: 65 | C25: Projected to age 110
A26: Annual annuity per policy | B26: 12000 | C26: Paid at end of year to survivors
A27: Expense per policy, year 1 | B27: 90
A28: Mortality multiplier | B28: 0.75 | C28: Annuitants live longer than the base table
A30: Stresses (Solvency II-style)
A31: Mortality: change in q (term) | B31: 0.15 | C31: SII Art. 137: +15%
A32: Longevity: change in q (annuity) | B32: -0.2 | C32: SII Art. 138: −20%
A33: Lapse up: change in lapse rate | B33: 0.5 | C33: SII Art. 142: +50%, capped at 100%
A34: Lapse down: change in lapse rate | B34: -0.5 | C34: SII Art. 142: −50% ...
A35: Lapse down: maximum absolute fall | B35: 0.2 | C35: ... capped at a fall of 20 percentage points
A36: Expense level: change | B36: 0.1 | C36: SII Art. 140: +10% (inflation stress left as exercise 6)
A38: Correlation between risks (Solvency II Art. 136)
B39: Mortality | C39: Longevity | D39: Lapse | E39: Expense
A40: Mortality | B40: 1 | C40: -0.25 | D40: 0 | E40: 0.25
A41: Longevity | B41: -0.25 | C41: 1 | D41: 0.25 | E41: 0.25
A42: Lapse | B42: 0 | C42: 0.25 | D42: 1 | E42: 0.5
A43: Expense | B43: 0.25 | C43: 0.25 | D43: 0.5 | E43: 1

Sheet Term
A1: Term assurance group: per-policy BEL on each basis, capital and exposures
A2: Per-policy BEL(t) = expense − premium + q × SA × v + (1 − q)(1 − lapse) × v × BEL(t+1). | H2: Capital = in-force × (stressed BEL − best-estimate BEL), floored at 0.
A3: Columns C–H: best estimate. I–P: stressed bases. Q–S: per-policy PVs used as exposures. T–AA: totals for the group.
A5: t | B5: Age | C5: q (best est.) | D5: Lapse rate | E5: Premium per policy | F5: Expense per policy | G5: In-force at start of year | H5: BEL per policy: best estimate | I5: q (mortality stress) | J5: BEL per policy: mortality stress | K5: Lapse (up stress) | L5: BEL per policy: lapse up | M5: Lapse (down stress) | N5: BEL per policy: lapse down | O5: Expense (stressed) | P5: BEL per policy: expense stress | Q5: PV future claims per policy | R5: PV future expenses per policy | S5: PV future premiums per policy | T5: BEL total (group) | U5: Capital: mortality | V5: Capital: lapse (worst of up/down) | W5: Capital: expense | X5: Exposure: sum assured in force | Y5: Exposure: PV future claims | Z5: Exposure: PV future profits | AA5: Exposure: PV future expenses | AB5: Check: BEL − (claims + expenses − premiums)
A6: 0 | B6: =Inputs!$B$14+A6 -> 40 | C6: =MIN(Inputs!$B$21*(1-EXP(-(Inputs!$B$8+Inputs!$B$9*Inputs!$B$10^B6))),1) -> 0.00050961528 | D6: =Inputs!$B$20 -> 0.05 | E6: =Inputs!$B$17 -> 400 | F6: =Inputs!$B$18*(1+Inputs!$B$19)^A6 -> 60 | G6: =Inputs!$B$13 -> 10000 | H6: =F6-E6+C6*Inputs!$B$16*(1/(1+Inputs!$B$6))+(1-C6)*(1-D6)*(1/(1+Inputs!$B$6))*H7 -> -1299.6781 | I6: =MIN(C6*(1+Inputs!$B$31),1) -> 0.00058605757 | J6: =F6-E6+I6*Inputs!$B$16*(1/(1+Inputs!$B$6))+(1-I6)*(1-D6)*(1/(1+Inputs!$B$6))*J7 -> -994.12088 | K6: =MIN(D6*(1+Inputs!$B$33),1) -> 0.075 | L6: =F6-E6+C6*Inputs!$B$16*(1/(1+Inputs!$B$6))+(1-C6)*(1-K6)*(1/(1+Inputs!$B$6))*L7 -> -1233.4987 | M6: =MAX(D6*(1+Inputs!$B$34),D6-Inputs!$B$35) -> 0.025 | N6: =F6-E6+C6*Inputs!$B$16*(1/(1+Inputs!$B$6))+(1-C6)*(1-M6)*(1/(1+Inputs!$B$6))*N7 -> -1348.0006 | O6: =F6*(1+Inputs!$B$36) -> 66 | P6: =O6-E6+C6*Inputs!$B$16*(1/(1+Inputs!$B$6))+(1-C6)*(1-D6)*(1/(1+Inputs!$B$6))*P7 -> -1223.207 | Q6: =C6*Inputs!$B$16*(1/(1+Inputs!$B$6))+(1-C6)*(1-D6)*(1/(1+Inputs!$B$6))*Q7 -> 2040.0115 | R6: =F6+(1-C6)*(1-D6)*(1/(1+Inputs!$B$6))*R7 -> 764.71177 | S6: =E6+(1-C6)*(1-D6)*(1/(1+Inputs!$B$6))*S7 -> 4104.4014 | T6: =G6*H6 -> -12996781 | U6: =G6*MAX(J6-H6,0) -> 3055572.5 | V6: =G6*MAX(L6-H6,N6-H6,0) -> 661794.1 | W6: =G6*MAX(P6-H6,0) -> 764711.77 | X6: =G6*Inputs!$B$16 -> 2000000000 | Y6: =G6*Q6 -> 20400115 | Z6: =G6*MAX(S6-Q6-R6,0) -> 12996781 | AA6: =G6*R6 -> 7647117.7 | AB6: =H6-(Q6+R6-S6) -> 0
A7: 1 | B7: =Inputs!$B$14+A7 -> 41 | C7: =MIN(Inputs!$B$21*(1-EXP(-(Inputs!$B$8+Inputs!$B$9*Inputs!$B$10^B7))),1) -> 0.00054552472 | D7: =Inputs!$B$20 -> 0.05 | E7: =Inputs!$B$17 -> 400 | F7: =Inputs!$B$18*(1+Inputs!$B$19)^A7 -> 61.8 | G7: =G6*(1-C6)*(1-D6) -> 9495.1587 | H7: =F7-E7+C7*Inputs!$B$16*(1/(1+Inputs!$B$6))+(1-C7)*(1-D7)*(1/(1+Inputs!$B$6))*H8 -> -1148.3658 | I7: =MIN(C7*(1+Inputs!$B$31),1) -> 0.00062735343 | J7: =F7-E7+I7*Inputs!$B$16*(1/(1+Inputs!$B$6))+(1-I7)*(1-D7)*(1/(1+Inputs!$B$6))*J8 -> -833.07352 | K7: =MIN(D7*(1+Inputs!$B$33),1) -> 0.075 | L7: =F7-E7+C7*Inputs!$B$16*(1/(1+Inputs!$B$6))+(1-C7)*(1-K7)*(1/(1+Inputs!$B$6))*L8 -> -1105.6735 | M7: =MAX(D7*(1+Inputs!$B$34),D7-Inputs!$B$35) -> 0.025 | N7: =F7-E7+C7*Inputs!$B$16*(1/(1+Inputs!$B$6))+(1-C7)*(1-M7)*(1/(1+Inputs!$B$6))*N8 -> -1169.9949 | O7: =F7*(1+Inputs!$B$36) -> 67.98 | P7: =O7-E7+C7*Inputs!$B$16*(1/(1+Inputs!$B$6))+(1-C7)*(1-D7)*(1/(1+Inputs!$B$6))*P8 -> -1071.9212 | Q7: =C7*Inputs!$B$16*(1/(1+Inputs!$B$6))+(1-C7)*(1-D7)*(1/(1+Inputs!$B$6))*Q8 -> 2105.5875 | R7: =F7+(1-C7)*(1-D7)*(1/(1+Inputs!$B$6))*R8 -> 764.4455 | S7: =E7+(1-C7)*(1-D7)*(1/(1+Inputs!$B$6))*S8 -> 4018.3988 | T7: =G7*H7 -> -10903915 | U7: =G7*MAX(J7-H7,0) -> 2993750.1 | V7: =G7*MAX(L7-H7,N7-H7,0) -> 405370.43 | W7: =G7*MAX(P7-H7,0) -> 725853.13 | X7: =G7*Inputs!$B$16 -> 1.8990317e+09 | Y7: =G7*Q7 -> 19992887 | Z7: =G7*MAX(S7-Q7-R7,0) -> 10903915 | AA7: =G7*R7 -> 7258531.3 | AB7: =H7-(Q7+R7-S7) -> 0
A8: 2 | B8: =Inputs!$B$14+A8 -> 42 | C8: =MIN(Inputs!$B$21*(1-EXP(-(Inputs!$B$8+Inputs!$B$9*Inputs!$B$10^B8))),1) -> 0.0005858854 | D8: =Inputs!$B$20 -> 0.05 | E8: =Inputs!$B$17 -> 400 | F8: =Inputs!$B$18*(1+Inputs!$B$19)^A8 -> 63.654 | G8: =G7*(1-C7)*(1-D7) -> 9015.4799 | H8: =F8-E8+C8*Inputs!$B$16*(1/(1+Inputs!$B$6))+(1-C8)*(1-D8)*(1/(1+Inputs!$B$6))*H9 -> -993.77971 | I8: =MIN(C8*(1+Inputs!$B$31),1) -> 0.00067376821 | J8: =F8-E8+I8*Inputs!$B$16*(1/(1+Inputs!$B$6))+(1-I8)*(1-D8)*(1/(1+Inputs!$B$6))*J9 -> -669.04121 | K8: =MIN(D8*(1+Inputs!$B$33),1) -> 0.075 | L8: =F8-E8+C8*Inputs!$B$16*(1/(1+Inputs!$B$6))+(1-C8)*(1-K8)*(1/(1+Inputs!$B$6))*L9 -> -973.07419 | M8: =MAX(D8*(1+Inputs!$B$34),D8-Inputs!$B$35) -> 0.025 | N8: =F8-E8+C8*Inputs!$B$16*(1/(1+Inputs!$B$6))+(1-C8)*(1-M8)*(1/(1+Inputs!$B$6))*N9 -> -991.15991 | O8: =F8*(1+Inputs!$B$36) -> 70.0194 | P8: =O8-E8+C8*Inputs!$B$16*(1/(1+Inputs!$B$6))+(1-C8)*(1-D8)*(1/(1+Inputs!$B$6))*P9 -> -917.55657 | Q8: =C8*Inputs!$B$16*(1/(1+Inputs!$B$6))+(1-C8)*(1-D8)*(1/(1+Inputs!$B$6))*Q9 -> 2169.2362 | R8: =F8+(1-C8)*(1-D8)*(1/(1+Inputs!$B$6))*R9 -> 762.23146 | S8: =E8+(1-C8)*(1-D8)*(1/(1+Inputs!$B$6))*S9 -> 3925.2474 | T8: =G8*H8 -> -8959401 | U8: =G8*MAX(J8-H8,0) -> 2927673.4 | V8: =G8*MAX(L8-H8,N8-H8,0) -> 186670.21 | W8: =G8*MAX(P8-H8,0) -> 687188.24 | X8: =G8*Inputs!$B$16 -> 1.803096e+09 | Y8: =G8*Q8 -> 19556705 | Z8: =G8*MAX(S8-Q8-R8,0) -> 8959401 | AA8: =G8*R8 -> 6871882.4 | AB8: =H8-(Q8+R8-S8) -> 0
A9: 3 | B9: =Inputs!$B$14+A9 -> 43 | C9: =MIN(Inputs!$B$21*(1-EXP(-(Inputs!$B$8+Inputs!$B$9*Inputs!$B$10^B9))),1) -> 0.00063124886 | D9: =Inputs!$B$20 -> 0.05 | E9: =Inputs!$B$17 -> 400 | F9: =Inputs!$B$18*(1+Inputs!$B$19)^A9 -> 65.56362 | G9: =G8*(1-C8)*(1-D8) -> 8559.6879 | H9: =F9-E9+C9*Inputs!$B$16*(1/(1+Inputs!$B$6))+(1-C9)*(1-D9)*(1/(1+Inputs!$B$6))*H10 -> -836.63102 | I9: =MIN(C9*(1+Inputs!$B$31),1) -> 0.00072593619 | J9: =F9-E9+I9*Inputs!$B$16*(1/(1+Inputs!$B$6))+(1-I9)*(1-D9)*(1/(1+Inputs!$B$6))*J10 -> -502.89642 | K9: =MIN(D9*(1+Inputs!$B$33),1) -> 0.075 | L9: =F9-E9+C9*Inputs!$B$16*(1/(1+Inputs!$B$6))+(1-C9)*(1-K9)*(1/(1+Inputs!$B$6))*L10 -> -836.17327 | M9: =MAX(D9*(1+Inputs!$B$34),D9-Inputs!$B$35) -> 0.025 | N9: =F9-E9+C9*Inputs!$B$16*(1/(1+Inputs!$B$6))+(1-C9)*(1-M9)*(1/(1+Inputs!$B$6))*N10 -> -812.40973 | O9: =F9*(1+Inputs!$B$36) -> 72.119982 | P9: =O9-E9+C9*Inputs!$B$16*(1/(1+Inputs!$B$6))+(1-C9)*(1-D9)*(1/(1+Inputs!$B$6))*P10 -> -760.84611 | Q9: =C9*Inputs!$B$16*(1/(1+Inputs!$B$6))+(1-C9)*(1-D9)*(1/(1+Inputs!$B$6))*Q10 -> 2229.8709 | R9: =F9+(1-C9)*(1-D9)*(1/(1+Inputs!$B$6))*R10 -> 757.84905 | S9: =E9+(1-C9)*(1-D9)*(1/(1+Inputs!$B$6))*S10 -> 3824.3509 | T9: =G9*H9 -> -7161300.4 | U9: =G9*MAX(J9-H9,0) -> 2856664 | V9: =G9*MAX(L9-H9,N9-H9,0) -> 207326.63 | W9: =G9*MAX(P9-H9,0) -> 648695.13 | X9: =G9*Inputs!$B$16 -> 1.7119376e+09 | Y9: =G9*Q9 -> 19086999 | Z9: =G9*MAX(S9-Q9-R9,0) -> 7161300.4 | AA9: =G9*R9 -> 6486951.3 | AB9: =H9-(Q9+R9-S9) -> 0
A10: 4 | B10: =Inputs!$B$14+A10 -> 44 | C10: =MIN(Inputs!$B$21*(1-EXP(-(Inputs!$B$8+Inputs!$B$9*Inputs!$B$10^B10))),1) -> 0.00068223493 | D10: =Inputs!$B$20 -> 0.05 | E10: =Inputs!$B$17 -> 400 | F10: =Inputs!$B$18*(1+Inputs!$B$19)^A10 -> 67.530529 | G10: =G9*(1-C9)*(1-D9) -> 8126.5704 | H10: =F10-E10+C10*Inputs!$B$16*(1/(1+Inputs!$B$6))+(1-C10)*(1-D10)*(1/(1+Inputs!$B$6))*H11 -> -677.80707 | I10: =MIN(C10*(1+Inputs!$B$31),1) -> 0.00078457017 | J10: =F10-E10+I10*Inputs!$B$16*(1/(1+Inputs!$B$6))+(1-I10)*(1-D10)*(1/(1+Inputs!$B$6))*J11 -> -335.71854 | K10: =MIN(D10*(1+Inputs!$B$33),1) -> 0.075 | L10: =F10-E10+C10*Inputs!$B$16*(1/(1+Inputs!$B$6))+(1-C10)*(1-K10)*(1/(1+Inputs!$B$6))*L11 -> -695.61616 | M10: =MAX(D10*(1+Inputs!$B$34),D10-Inputs!$B$35) -> 0.025 | N10: =F10-E10+C10*Inputs!$B$16*(1/(1+Inputs!$B$6))+(1-C10)*(1-M10)*(1/(1+Inputs!$B$6))*N11 -> -634.82363 | O10: =F10*(1+Inputs!$B$36) -> 74.283581 | P10: =O10-E10+C10*Inputs!$B$16*(1/(1+Inputs!$B$6))+(1-C10)*(1-D10)*(1/(1+Inputs!$B$6))*P11 -> -602.70135 | Q10: =C10*Inputs!$B$16*(1/(1+Inputs!$B$6))+(1-C10)*(1-D10)*(1/(1+Inputs!$B$6))*Q11 -> 2286.1981 | R10: =F10+(1-C10)*(1-D10)*(1/(1+Inputs!$B$6))*R11 -> 751.05725 | S10: =E10+(1-C10)*(1-D10)*(1/(1+Inputs!$B$6))*S11 -> 3715.0625 | T10: =G10*H10 -> -5508246.9 | U10: =G10*MAX(J10-H10,0) -> 2780006.6 | V10: =G10*MAX(L10-H10,N10-H10,0) -> 349307.98 | W10: =G10*MAX(P10-H10,0) -> 610351.96 | X10: =G10*Inputs!$B$16 -> 1.6253141e+09 | Y10: =G10*Q10 -> 18578950 | Z10: =G10*MAX(S10-Q10-R10,0) -> 5508246.9 | AA10: =G10*R10 -> 6103519.6 | AB10: =H10-(Q10+R10-S10) -> 0
A11: 5 | B11: =Inputs!$B$14+A11 -> 45 | C11: =MIN(Inputs!$B$21*(1-EXP(-(Inputs!$B$8+Inputs!$B$9*Inputs!$B$10^B11))),1) -> 0.00073954016 | D11: =Inputs!$B$20 -> 0.05 | E11: =Inputs!$B$17 -> 400 | F11: =Inputs!$B$18*(1+Inputs!$B$19)^A11 -> 69.556444 | G11: =G10*(1-C10)*(1-D10) -> 7714.9749 | H11: =F11-E11+C11*Inputs!$B$16*(1/(1+Inputs!$B$6))+(1-C11)*(1-D11)*(1/(1+Inputs!$B$6))*H12 -> -518.40074 | I11: =MIN(C11*(1+Inputs!$B$31),1) -> 0.00085047119 | J11: =F11-E11+I11*Inputs!$B$16*(1/(1+Inputs!$B$6))+(1-I11)*(1-D11)*(1/(1+Inputs!$B$6))*J12 -> -168.82779 | K11: =MIN(D11*(1+Inputs!$B$33),1) -> 0.075 | L11: =F11-E11+C11*Inputs!$B$16*(1/(1+Inputs!$B$6))+(1-C11)*(1-K11)*(1/(1+Inputs!$B$6))*L12 -> -552.25577 | M11: =MAX(D11*(1+Inputs!$B$34),D11-Inputs!$B$35) -> 0.025 | N11: =F11-E11+C11*Inputs!$B$16*(1/(1+Inputs!$B$6))+(1-C11)*(1-M11)*(1/(1+Inputs!$B$6))*N12 -> -459.66926 | O11: =F11*(1+Inputs!$B$36) -> 76.512089 | P11: =O11-E11+C11*Inputs!$B$16*(1/(1+Inputs!$B$6))+(1-C11)*(1-D11)*(1/(1+Inputs!$B$6))*P12 -> -444.24146 | Q11: =C11*Inputs!$B$16*(1/(1+Inputs!$B$6))+(1-C11)*(1-D11)*(1/(1+Inputs!$B$6))*Q12 -> 2336.6859 | R11: =F11+(1-C11)*(1-D11)*(1/(1+Inputs!$B$6))*R12 -> 741.59281 | S11: =E11+(1-C11)*(1-D11)*(1/(1+Inputs!$B$6))*S12 -> 3596.6794 | T11: =G11*H11 -> -3999448.7 | U11: =G11*MAX(J11-H11,0) -> 2696946.5 | V11: =G11*MAX(L11-H11,N11-H11,0) -> 453111.87 | W11: =G11*MAX(P11-H11,0) -> 572136.99 | X11: =G11*Inputs!$B$16 -> 1.542995e+09 | Y11: =G11*Q11 -> 18027473 | Z11: =G11*MAX(S11-Q11-R11,0) -> 3999448.7 | AA11: =G11*R11 -> 5721369.9 | AB11: =H11-(Q11+R11-S11) -> 0
A12: 6 | B12: =Inputs!$B$14+A12 -> 46 | C12: =MIN(Inputs!$B$21*(1-EXP(-(Inputs!$B$8+Inputs!$B$9*Inputs!$B$10^B12))),1) -> 0.00080394732 | D12: =Inputs!$B$20 -> 0.05 | E12: =Inputs!$B$17 -> 400 | F12: =Inputs!$B$18*(1+Inputs!$B$19)^A12 -> 71.643138 | G12: =G11*(1-C11)*(1-D11) -> 7323.8059 | H12: =F12-E12+C12*Inputs!$B$16*(1/(1+Inputs!$B$6))+(1-C12)*(1-D12)*(1/(1+Inputs!$B$6))*H13 -> -359.74387 | I12: =MIN(C12*(1+Inputs!$B$31),1) -> 0.00092453942 | J12: =F12-E12+I12*Inputs!$B$16*(1/(1+Inputs!$B$6))+(1-I12)*(1-D12)*(1/(1+Inputs!$B$6))*J13 -> -3.8243076 | K12: =MIN(D12*(1+Inputs!$B$33),1) -> 0.075 | L12: =F12-E12+C12*Inputs!$B$16*(1/(1+Inputs!$B$6))+(1-C12)*(1-K12)*(1/(1+Inputs!$B$6))*L13 -> -407.1926 | M12: =MAX(D12*(1+Inputs!$B$34),D12-Inputs!$B$35) -> 0.025 | N12: =F12-E12+C12*Inputs!$B$16*(1/(1+Inputs!$B$6))+(1-C12)*(1-M12)*(1/(1+Inputs!$B$6))*N13 -> -288.42921 | O12: =F12*(1+Inputs!$B$36) -> 78.807452 | P12: =O12-E12+C12*Inputs!$B$16*(1/(1+Inputs!$B$6))+(1-C12)*(1-D12)*(1/(1+Inputs!$B$6))*P13 -> -286.82705 | Q12: =C12*Inputs!$B$16*(1/(1+Inputs!$B$6))+(1-C12)*(1-D12)*(1/(1+Inputs!$B$6))*Q13 -> 2379.5265 | R12: =F12+(1-C12)*(1-D12)*(1/(1+Inputs!$B$6))*R13 -> 729.16815 | S12: =E12+(1-C12)*(1-D12)*(1/(1+Inputs!$B$6))*S13 -> 3468.4385 | T12: =G12*H12 -> -2634694.3 | U12: =G12*MAX(J12-H12,0) -> 2606685.8 | V12: =G12*MAX(L12-H12,N12-H12,0) -> 522294.69 | W12: =G12*MAX(P12-H12,0) -> 534028.6 | X12: =G12*Inputs!$B$16 -> 1.4647612e+09 | Y12: =G12*Q12 -> 17427190 | Z12: =G12*MAX(S12-Q12-R12,0) -> 2634694.3 | AA12: =G12*R12 -> 5340286 | AB12: =H12-(Q12+R12-S12) -> 5.6843419e-13
A13: 7 | B13: =Inputs!$B$14+A13 -> 47 | C13: =MIN(Inputs!$B$21*(1-EXP(-(Inputs!$B$8+Inputs!$B$9*Inputs!$B$10^B13))),1) -> 0.00087633602 | D13: =Inputs!$B$20 -> 0.05 | E13: =Inputs!$B$17 -> 400 | F13: =Inputs!$B$18*(1+Inputs!$B$19)^A13 -> 73.792432 | G13: =G12*(1-C12)*(1-D12) -> 6952.022 | H13: =F13-E13+C13*Inputs!$B$16*(1/(1+Inputs!$B$6))+(1-C13)*(1-D13)*(1/(1+Inputs!$B$6))*H14 -> -203.44575 | I13: =MIN(C13*(1+Inputs!$B$31),1) -> 0.0010077864 | J13: =F13-E13+I13*Inputs!$B$16*(1/(1+Inputs!$B$6))+(1-I13)*(1-D13)*(1/(1+Inputs!$B$6))*J14 -> 157.36723 | K13: =MIN(D13*(1+Inputs!$B$33),1) -> 0.075 | L13: =F13-E13+C13*Inputs!$B$16*(1/(1+Inputs!$B$6))+(1-C13)*(1-K13)*(1/(1+Inputs!$B$6))*L14 -> -261.8216 | M13: =MAX(D13*(1+Inputs!$B$34),D13-Inputs!$B$35) -> 0.025 | N13: =F13-E13+C13*Inputs!$B$16*(1/(1+Inputs!$B$6))+(1-C13)*(1-M13)*(1/(1+Inputs!$B$6))*N14 -> -122.83104 | O13: =F13*(1+Inputs!$B$36) -> 81.171675 | P13: =O13-E13+C13*Inputs!$B$16*(1/(1+Inputs!$B$6))+(1-C13)*(1-D13)*(1/(1+Inputs!$B$6))*P14 -> -132.09884 | Q13: =C13*Inputs!$B$16*(1/(1+Inputs!$B$6))+(1-C13)*(1-D13)*(1/(1+Inputs!$B$6))*Q14 -> 2412.5952 | R13: =F13+(1-C13)*(1-D13)*(1/(1+Inputs!$B$6))*R14 -> 713.46913 | S13: =E13+(1-C13)*(1-D13)*(1/(1+Inputs!$B$6))*S14 -> 3329.5101 | T13: =G13*H13 -> -1414359.3 | U13: =G13*MAX(J13-H13,0) -> 2508379.8 | V13: =G13*MAX(L13-H13,N13-H13,0) -> 560435.22 | W13: =G13*MAX(P13-H13,0) -> 496005.31 | X13: =G13*Inputs!$B$16 -> 1.3904044e+09 | Y13: =G13*Q13 -> 16772415 | Z13: =G13*MAX(S13-Q13-R13,0) -> 1414359.3 | AA13: =G13*R13 -> 4960053.1 | AB13: =H13-(Q13+R13-S13) -> 0
A14: 8 | B14: =Inputs!$B$14+A14 -> 48 | C14: =MIN(Inputs!$B$21*(1-EXP(-(Inputs!$B$8+Inputs!$B$9*Inputs!$B$10^B14))),1) -> 0.00095769465 | D14: =Inputs!$B$20 -> 0.05 | E14: =Inputs!$B$17 -> 400 | F14: =Inputs!$B$18*(1+Inputs!$B$19)^A14 -> 76.006205 | G14: =G13*(1-C13)*(1-D13) -> 6598.6332 | H14: =F14-E14+C14*Inputs!$B$16*(1/(1+Inputs!$B$6))+(1-C14)*(1-D14)*(1/(1+Inputs!$B$6))*H15 -> -51.437216 | I14: =MIN(C14*(1+Inputs!$B$31),1) -> 0.0011013488 | J14: =F14-E14+I14*Inputs!$B$16*(1/(1+Inputs!$B$6))+(1-I14)*(1-D14)*(1/(1+Inputs!$B$6))*J15 -> 312.4462 | K14: =MIN(D14*(1+Inputs!$B$33),1) -> 0.075 | L14: =F14-E14+C14*Inputs!$B$16*(1/(1+Inputs!$B$6))+(1-C14)*(1-K14)*(1/(1+Inputs!$B$6))*L15 -> -117.88672 | M14: =MAX(D14*(1+Inputs!$B$34),D14-Inputs!$B$35) -> 0.025 | N14: =F14-E14+C14*Inputs!$B$16*(1/(1+Inputs!$B$6))+(1-C14)*(1-M14)*(1/(1+Inputs!$B$6))*N15 -> 35.118586 | O14: =F14*(1+Inputs!$B$36) -> 83.606825 | P14: =O14-E14+C14*Inputs!$B$16*(1/(1+Inputs!$B$6))+(1-C14)*(1-D14)*(1/(1+Inputs!$B$6))*P15 -> 17.978036 | Q14: =C14*Inputs!$B$16*(1/(1+Inputs!$B$6))+(1-C14)*(1-D14)*(1/(1+Inputs!$B$6))*Q15 -> 2433.4018 | R14: =F14+(1-C14)*(1-D14)*(1/(1+Inputs!$B$6))*R15 -> 694.15252 | S14: =E14+(1-C14)*(1-D14)*(1/(1+Inputs!$B$6))*S15 -> 3178.9915 | T14: =G14*H14 -> -339415.32 | U14: =G14*MAX(J14-H14,0) -> 2401133.2 | V14: =G14*MAX(L14-H14,N14-H14,0) -> 571149.99 | W14: =G14*MAX(P14-H14,0) -> 458045.79 | X14: =G14*Inputs!$B$16 -> 1.3197266e+09 | Y14: =G14*Q14 -> 16057126 | Z14: =G14*MAX(S14-Q14-R14,0) -> 339415.32 | AA14: =G14*R14 -> 4580457.9 | AB14: =H14-(Q14+R14-S14) -> -2.1316282e-13
A15: 9 | B15: =Inputs!$B$14+A15 -> 49 | C15: =MIN(Inputs!$B$21*(1-EXP(-(Inputs!$B$8+Inputs!$B$9*Inputs!$B$10^B15))),1) -> 0.0010491338 | D15: =Inputs!$B$20 -> 0.05 | E15: =Inputs!$B$17 -> 400 | F15: =Inputs!$B$18*(1+Inputs!$B$19)^A15 -> 78.286391 | G15: =G14*(1-C14)*(1-D14) -> 6262.6981 | H15: =F15-E15+C15*Inputs!$B$16*(1/(1+Inputs!$B$6))+(1-C15)*(1-D15)*(1/(1+Inputs!$B$6))*H16 -> 93.978788 | I15: =MIN(C15*(1+Inputs!$B$31),1) -> 0.0012065039 | J15: =F15-E15+I15*Inputs!$B$16*(1/(1+Inputs!$B$6))+(1-I15)*(1-D15)*(1/(1+Inputs!$B$6))*J16 -> 458.67719 | K15: =MIN(D15*(1+Inputs!$B$33),1) -> 0.075 | L15: =F15-E15+C15*Inputs!$B$16*(1/(1+Inputs!$B$6))+(1-C15)*(1-K15)*(1/(1+Inputs!$B$6))*L16 -> 22.4554 | M15: =MAX(D15*(1+Inputs!$B$34),D15-Inputs!$B$35) -> 0.025 | N15: =F15-E15+C15*Inputs!$B$16*(1/(1+Inputs!$B$6))+(1-C15)*(1-M15)*(1/(1+Inputs!$B$6))*N16 -> 183.09517 | O15: =F15*(1+Inputs!$B$36) -> 86.11503 | P15: =O15-E15+C15*Inputs!$B$16*(1/(1+Inputs!$B$6))+(1-C15)*(1-D15)*(1/(1+Inputs!$B$6))*P16 -> 161.06311 | Q15: =C15*Inputs!$B$16*(1/(1+Inputs!$B$6))+(1-C15)*(1-D15)*(1/(1+Inputs!$B$6))*Q16 -> 2439.0358 | R15: =F15+(1-C15)*(1-D15)*(1/(1+Inputs!$B$6))*R16 -> 670.8432 | S15: =E15+(1-C15)*(1-D15)*(1/(1+Inputs!$B$6))*S16 -> 3015.9002 | T15: =G15*H15 -> 588560.78 | U15: =G15*MAX(J15-H15,0) -> 2283996 | V15: =G15*MAX(L15-H15,N15-H15,0) -> 558108.97 | W15: =G15*MAX(P15-H15,0) -> 420128.84 | X15: =G15*Inputs!$B$16 -> 1.2525396e+09 | Y15: =G15*Q15 -> 15274945 | Z15: =G15*MAX(S15-Q15-R15,0) -> 0 | AA15: =G15*R15 -> 4201288.4 | AB15: =H15-(Q15+R15-S15) -> -3.9790393e-13
A16: 10 | B16: =Inputs!$B$14+A16 -> 50 | C16: =MIN(Inputs!$B$21*(1-EXP(-(Inputs!$B$8+Inputs!$B$9*Inputs!$B$10^B16))),1) -> 0.0011519015 | D16: =Inputs!$B$20 -> 0.05 | E16: =Inputs!$B$17 -> 400 | F16: =Inputs!$B$18*(1+Inputs!$B$19)^A16 -> 80.634983 | G16: =G15*(1-C15)*(1-D15) -> 5943.3213 | H16: =F16-E16+C16*Inputs!$B$16*(1/(1+Inputs!$B$6))+(1-C16)*(1-D16)*(1/(1+Inputs!$B$6))*H17 -> 230.06916 | I16: =MIN(C16*(1+Inputs!$B$31),1) -> 0.0013246867 | J16: =F16-E16+I16*Inputs!$B$16*(1/(1+Inputs!$B$6))+(1-I16)*(1-D16)*(1/(1+Inputs!$B$6))*J17 -> 592.82233 | K16: =MIN(D16*(1+Inputs!$B$33),1) -> 0.075 | L16: =F16-E16+C16*Inputs!$B$16*(1/(1+Inputs!$B$6))+(1-C16)*(1-K16)*(1/(1+Inputs!$B$6))*L17 -> 156.56135 | M16: =MAX(D16*(1+Inputs!$B$34),D16-Inputs!$B$35) -> 0.025 | N16: =F16-E16+C16*Inputs!$B$16*(1/(1+Inputs!$B$6))+(1-C16)*(1-M16)*(1/(1+Inputs!$B$6))*N17 -> 318.41228 | O16: =F16*(1+Inputs!$B$36) -> 88.698481 | P16: =O16-E16+C16*Inputs!$B$16*(1/(1+Inputs!$B$6))+(1-C16)*(1-D16)*(1/(1+Inputs!$B$6))*P17 -> 294.38227 | Q16: =C16*Inputs!$B$16*(1/(1+Inputs!$B$6))+(1-C16)*(1-D16)*(1/(1+Inputs!$B$6))*Q17 -> 2426.1033 | R16: =F16+(1-C16)*(1-D16)*(1/(1+Inputs!$B$6))*R17 -> 643.13107 | S16: =E16+(1-C16)*(1-D16)*(1/(1+Inputs!$B$6))*S17 -> 2839.1652 | T16: =G16*H16 -> 1367375 | U16: =G16*MAX(J16-H16,0) -> 2155958.6 | V16: =G16*MAX(L16-H16,N16-H16,0) -> 525051.54 | W16: =G16*MAX(P16-H16,0) -> 382233.45 | X16: =G16*Inputs!$B$16 -> 1.1886643e+09 | Y16: =G16*Q16 -> 14419111 | Z16: =G16*MAX(S16-Q16-R16,0) -> 0 | AA16: =G16*R16 -> 3822334.5 | AB16: =H16-(Q16+R16-S16) -> 0
A17: 11 | B17: =Inputs!$B$14+A17 -> 51 | C17: =MIN(Inputs!$B$21*(1-EXP(-(Inputs!$B$8+Inputs!$B$9*Inputs!$B$10^B17))),1) -> 0.0012673997 | D17: =Inputs!$B$20 -> 0.05 | E17: =Inputs!$B$17 -> 400 | F17: =Inputs!$B$18*(1+Inputs!$B$19)^A17 -> 83.054032 | G17: =G16*(1-C16)*(1-D16) -> 5639.6514 | H17: =F17-E17+C17*Inputs!$B$16*(1/(1+Inputs!$B$6))+(1-C17)*(1-D17)*(1/(1+Inputs!$B$6))*H18 -> 353.60406 | I17: =MIN(C17*(1+Inputs!$B$31),1) -> 0.0014575097 | J17: =F17-E17+I17*Inputs!$B$16*(1/(1+Inputs!$B$6))+(1-I17)*(1-D17)*(1/(1+Inputs!$B$6))*J18 -> 711.06365 | K17: =MIN(D17*(1+Inputs!$B$33),1) -> 0.075 | L17: =F17-E17+C17*Inputs!$B$16*(1/(1+Inputs!$B$6))+(1-C17)*(1-K17)*(1/(1+Inputs!$B$6))*L18 -> 281.21458 | M17: =MAX(D17*(1+Inputs!$B$34),D17-Inputs!$B$35) -> 0.025 | N17: =F17-E17+C17*Inputs!$B$16*(1/(1+Inputs!$B$6))+(1-C17)*(1-M17)*(1/(1+Inputs!$B$6))*N18 -> 437.97149 | O17: =F17*(1+Inputs!$B$36) -> 91.359435 | P17: =O17-E17+C17*Inputs!$B$16*(1/(1+Inputs!$B$6))+(1-C17)*(1-D17)*(1/(1+Inputs!$B$6))*P18 -> 414.66081 | Q17: =C17*Inputs!$B$16*(1/(1+Inputs!$B$6))+(1-C17)*(1-D17)*(1/(1+Inputs!$B$6))*Q18 -> 2390.6549 | R17: =F17+(1-C17)*(1-D17)*(1/(1+Inputs!$B$6))*R18 -> 610.56749 | S17: =E17+(1-C17)*(1-D17)*(1/(1+Inputs!$B$6))*S18 -> 2647.6184 | T17: =G17*H17 -> 1994203.6 | U17: =G17*MAX(J17-H17,0) -> 2015947.5 | V17: =G17*MAX(L17-H17,N17-H17,0) -> 475802.92 | W17: =G17*MAX(P17-H17,0) -> 344338.78 | X17: =G17*Inputs!$B$16 -> 1.1279303e+09 | Y17: =G17*Q17 -> 13482460 | Z17: =G17*MAX(S17-Q17-R17,0) -> 0 | AA17: =G17*R17 -> 3443387.8 | AB17: =H17-(Q17+R17-S17) -> 0
A18: 12 | B18: =Inputs!$B$14+A18 -> 52 | C18: =MIN(Inputs!$B$21*(1-EXP(-(Inputs!$B$8+Inputs!$B$9*Inputs!$B$10^B18))),1) -> 0.0013972038 | D18: =Inputs!$B$20 -> 0.05 | E18: =Inputs!$B$17 -> 400 | F18: =Inputs!$B$18*(1+Inputs!$B$19)^A18 -> 85.545653 | G18: =G17*(1-C17)*(1-D17) -> 5350.8785 | H18: =F18-E18+C18*Inputs!$B$16*(1/(1+Inputs!$B$6))+(1-C18)*(1-D18)*(1/(1+Inputs!$B$6))*H19 -> 460.78039 | I18: =MIN(C18*(1+Inputs!$B$31),1) -> 0.0016067844 | J18: =F18-E18+I18*Inputs!$B$16*(1/(1+Inputs!$B$6))+(1-I18)*(1-D18)*(1/(1+Inputs!$B$6))*J19 -> 808.91369 | K18: =MIN(D18*(1+Inputs!$B$33),1) -> 0.075 | L18: =F18-E18+C18*Inputs!$B$16*(1/(1+Inputs!$B$6))+(1-C18)*(1-K18)*(1/(1+Inputs!$B$6))*L19 -> 392.52496 | M18: =MAX(D18*(1+Inputs!$B$34),D18-Inputs!$B$35) -> 0.025 | N18: =F18-E18+C18*Inputs!$B$16*(1/(1+Inputs!$B$6))+(1-C18)*(1-M18)*(1/(1+Inputs!$B$6))*N19 -> 538.20523 | O18: =F18*(1+Inputs!$B$36) -> 94.100219 | P18: =O18-E18+C18*Inputs!$B$16*(1/(1+Inputs!$B$6))+(1-C18)*(1-D18)*(1/(1+Inputs!$B$6))*P19 -> 518.04653 | Q18: =C18*Inputs!$B$16*(1/(1+Inputs!$B$6))+(1-C18)*(1-D18)*(1/(1+Inputs!$B$6))*Q19 -> 2328.1029 | R18: =F18+(1-C18)*(1-D18)*(1/(1+Inputs!$B$6))*R19 -> 572.66143 | S18: =E18+(1-C18)*(1-D18)*(1/(1+Inputs!$B$6))*S19 -> 2439.9839 | T18: =G18*H18 -> 2465579.9 | U18: =G18*MAX(J18-H18,0) -> 1862819 | V18: =G18*MAX(L18-H18,N18-H18,0) -> 414290.93 | W18: =G18*MAX(P18-H18,0) -> 306424.18 | X18: =G18*Inputs!$B$16 -> 1.0701757e+09 | Y18: =G18*Q18 -> 12457396 | Z18: =G18*MAX(S18-Q18-R18,0) -> 0 | AA18: =G18*R18 -> 3064241.8 | AB18: =H18-(Q18+R18-S18) -> 0
... A25: 19 | B25: =Inputs!$B$14+A25 -> 59 | C25: =MIN(Inputs!$B$21*(1-EXP(-(Inputs!$B$8+Inputs!$B$9*Inputs!$B$10^B25))),1) -> 0.0028862256 | D25: =Inputs!$B$20 -> 0.05 | E25: =Inputs!$B$17 -> 400 | F25: =Inputs!$B$18*(1+Inputs!$B$19)^A25 -> 105.21036 | G25: =G24*(1-C24)*(1-D24) -> 3686.3385 | H25: =F25-E25+C25*Inputs!$B$16*(1/(1+Inputs!$B$6))+(1-C25)*(1-D25)*(1/(1+Inputs!$B$6))*H26 -> 265.64253 | I25: =MIN(C25*(1+Inputs!$B$31),1) -> 0.0033191595 | J25: =F25-E25+I25*Inputs!$B$16*(1/(1+Inputs!$B$6))+(1-I25)*(1-D25)*(1/(1+Inputs!$B$6))*J26 -> 349.70735 | K25: =MIN(D25*(1+Inputs!$B$33),1) -> 0.075 | L25: =F25-E25+C25*Inputs!$B$16*(1/(1+Inputs!$B$6))+(1-C25)*(1-K25)*(1/(1+Inputs!$B$6))*L26 -> 265.64253 | M25: =MAX(D25*(1+Inputs!$B$34),D25-Inputs!$B$35) -> 0.025 | N25: =F25-E25+C25*Inputs!$B$16*(1/(1+Inputs!$B$6))+(1-C25)*(1-M25)*(1/(1+Inputs!$B$6))*N26 -> 265.64253 | O25: =F25*(1+Inputs!$B$36) -> 115.7314 | P25: =O25-E25+C25*Inputs!$B$16*(1/(1+Inputs!$B$6))+(1-C25)*(1-D25)*(1/(1+Inputs!$B$6))*P26 -> 276.16356 | Q25: =C25*Inputs!$B$16*(1/(1+Inputs!$B$6))+(1-C25)*(1-D25)*(1/(1+Inputs!$B$6))*Q26 -> 560.43216 | R25: =F25+(1-C25)*(1-D25)*(1/(1+Inputs!$B$6))*R26 -> 105.21036 | S25: =E25+(1-C25)*(1-D25)*(1/(1+Inputs!$B$6))*S26 -> 400 | T25: =G25*H25 -> 979248.26 | U25: =G25*MAX(J25-H25,0) -> 309891.4 | V25: =G25*MAX(L25-H25,N25-H25,0) -> 0 | W25: =G25*MAX(P25-H25,0) -> 38784.101 | X25: =G25*Inputs!$B$16 -> 7.3726769e+08 | Y25: =G25*Q25 -> 2065942.6 | Z25: =G25*MAX(S25-Q25-R25,0) -> 0 | AA25: =G25*R25 -> 387841.01 | AB25: =H25-(Q25+R25-S25) -> 0
A26: end | H26: 0 | J26: 0 | L26: 0 | N26: 0 | P26: 0 | Q26: 0 | R26: 0 | S26: 0

Sheet Annuity
A1: Immediate annuity group: per-policy BEL on each basis, capital and exposures
A2: Per-policy BEL(t) = expense + (1 − q) × annuity × v + (1 − q) × v × BEL(t+1).
A3: Capital = in-force × (stressed BEL − best-estimate BEL), floored at 0.
A5: t | B5: Age | C5: q (best est.) | D5: Annuity per survivor | E5: Expense per policy | F5: In-force at start of year | G5: BEL per policy: best estimate | H5: q (longevity stress) | I5: BEL per policy: longevity stress | J5: Expense (stressed) | K5: BEL per policy: expense stress | L5: PV future annuity payments per policy | M5: PV future expenses per policy | N5: BEL total (group) | O5: Capital: longevity | P5: Capital: expense | Q5: Exposure: PV future annuity payments | R5: Exposure: PV future expenses
A6: 0 | B6: =Inputs!$B$25+A6 -> 65 | C6: =MIN(Inputs!$B$28*(1-EXP(-(Inputs!$B$8+Inputs!$B$9*Inputs!$B$10^B6))),1) -> 0.0041918827 | D6: =Inputs!$B$26 -> 12000 | E6: =Inputs!$B$27*(1+Inputs!$B$19)^A6 -> 90 | F6: =Inputs!$B$24 -> 300 | G6: =E6+(1-C6)*D6*(1/(1+Inputs!$B$6))+(1-C6)*(1/(1+Inputs!$B$6))*G7 -> 203497.22 | H6: =MIN(MAX(C6*(1+Inputs!$B$32),0),1) -> 0.0033535061 | I6: =E6+(1-H6)*D6*(1/(1+Inputs!$B$6))+(1-H6)*(1/(1+Inputs!$B$6))*I7 -> 213617.71 | J6: =E6*(1+Inputs!$B$36) -> 99 | K6: =J6+(1-C6)*D6*(1/(1+Inputs!$B$6))+(1-C6)*(1/(1+Inputs!$B$6))*K7 -> 203730.99 | L6: =(1-C6)*D6*(1/(1+Inputs!$B$6))+(1-C6)*(1/(1+Inputs!$B$6))*L7 -> 201159.51 | M6: =E6+(1-C6)*(1/(1+Inputs!$B$6))*M7 -> 2337.7056 | N6: =F6*G6 -> 61049166 | O6: =F6*MAX(I6-G6,0) -> 3036146.4 | P6: =F6*MAX(K6-G6,0) -> 70131.167 | Q6: =F6*L6 -> 60347854 | R6: =F6*M6 -> 701311.67
A7: 1 | B7: =Inputs!$B$25+A7 -> 66 | C7: =MIN(Inputs!$B$28*(1-EXP(-(Inputs!$B$8+Inputs!$B$9*Inputs!$B$10^B7))),1) -> 0.0046897089 | D7: =Inputs!$B$26 -> 12000 | E7: =Inputs!$B$27*(1+Inputs!$B$19)^A7 -> 92.7 | F7: =F6*(1-C6) -> 298.74244 | G7: =E7+(1-C7)*D7*(1/(1+Inputs!$B$6))+(1-C7)*(1/(1+Inputs!$B$6))*G8 -> 198391.37 | H7: =MIN(MAX(C7*(1+Inputs!$B$32),0),1) -> 0.0037517671 | I7: =E7+(1-H7)*D7*(1/(1+Inputs!$B$6))+(1-H7)*(1/(1+Inputs!$B$6))*I8 -> 208673.57 | J7: =E7*(1+Inputs!$B$36) -> 101.97 | K7: =J7+(1-C7)*D7*(1/(1+Inputs!$B$6))+(1-C7)*(1/(1+Inputs!$B$6))*K8 -> 198623.86 | L7: =(1-C7)*D7*(1/(1+Inputs!$B$6))+(1-C7)*(1/(1+Inputs!$B$6))*L8 -> 196066.49 | M7: =E7+(1-C7)*(1/(1+Inputs!$B$6))*M8 -> 2324.8824 | N7: =F7*G7 -> 59267921 | O7: =F7*MAX(I7-G7,0) -> 3071728.5 | P7: =F7*MAX(K7-G7,0) -> 69454.102 | Q7: =F7*L7 -> 58573380 | R7: =F7*M7 -> 694541.02
A8: 2 | B8: =Inputs!$B$25+A8 -> 67 | C8: =MIN(Inputs!$B$28*(1-EXP(-(Inputs!$B$8+Inputs!$B$9*Inputs!$B$10^B8))),1) -> 0.005248869 | D8: =Inputs!$B$26 -> 12000 | E8: =Inputs!$B$27*(1+Inputs!$B$19)^A8 -> 95.481 | F8: =F7*(1-C7) -> 297.34142 | G8: =E8+(1-C8)*D8*(1/(1+Inputs!$B$6))+(1-C8)*(1/(1+Inputs!$B$6))*G9 -> 193210.01 | H8: =MIN(MAX(C8*(1+Inputs!$B$32),0),1) -> 0.0041990952 | I8: =E8+(1-H8)*D8*(1/(1+Inputs!$B$6))+(1-H8)*(1/(1+Inputs!$B$6))*I9 -> 203647.35 | J8: =E8*(1+Inputs!$B$36) -> 105.0291 | K8: =J8+(1-C8)*D8*(1/(1+Inputs!$B$6))+(1-C8)*(1/(1+Inputs!$B$6))*K9 -> 193441 | L8: =(1-C8)*D8*(1/(1+Inputs!$B$6))+(1-C8)*(1/(1+Inputs!$B$6))*L9 -> 190900.03 | M8: =E8+(1-C8)*(1/(1+Inputs!$B$6))*M9 -> 2309.981 | N8: =F8*G8 -> 57449338 | O8: =F8*MAX(I8-G8,0) -> 3103455.3 | P8: =F8*MAX(K8-G8,0) -> 68685.302 | Q8: =F8*L8 -> 56762485 | R8: =F8*M8 -> 686853.02
A9: 3 | B9: =Inputs!$B$25+A9 -> 68 | C9: =MIN(Inputs!$B$28*(1-EXP(-(Inputs!$B$8+Inputs!$B$9*Inputs!$B$10^B9))),1) -> 0.0058768641 | D9: =Inputs!$B$26 -> 12000 | E9: =Inputs!$B$27*(1+Inputs!$B$19)^A9 -> 98.34543 | F9: =F8*(1-C8) -> 295.78071 | G9: =E9+(1-C9)*D9*(1/(1+Inputs!$B$6))+(1-C9)*(1/(1+Inputs!$B$6))*G10 -> 187957.51 | H9: =MIN(MAX(C9*(1+Inputs!$B$32),0),1) -> 0.0047014913 | I9: =E9+(1-H9)*D9*(1/(1+Inputs!$B$6))+(1-H9)*(1/(1+Inputs!$B$6))*I10 -> 198542.52 | J9: =E9*(1+Inputs!$B$36) -> 108.17997 | K9: =J9+(1-C9)*D9*(1/(1+Inputs!$B$6))+(1-C9)*(1/(1+Inputs!$B$6))*K10 -> 188186.81 | L9: =(1-C9)*D9*(1/(1+Inputs!$B$6))+(1-C9)*(1/(1+Inputs!$B$6))*L10 -> 185664.54 | M9: =E9+(1-C9)*(1/(1+Inputs!$B$6))*M10 -> 2292.9705 | N9: =F9*G9 -> 55594207 | O9: =F9*MAX(I9-G9,0) -> 3130840 | P9: =F9*MAX(K9-G9,0) -> 67821.644 | Q9: =F9*L9 -> 54915991 | R9: =F9*M9 -> 678216.44
A10: 4 | B10: =Inputs!$B$25+A10 -> 69 | C10: =MIN(Inputs!$B$28*(1-EXP(-(Inputs!$B$8+Inputs!$B$9*Inputs!$B$10^B10))),1) -> 0.0065820986 | D10: =Inputs!$B$26 -> 12000 | E10: =Inputs!$B$27*(1+Inputs!$B$19)^A10 -> 101.29579 | F10: =F9*(1-C9) -> 294.04245 | G10: =E10+(1-C10)*D10*(1/(1+Inputs!$B$6))+(1-C10)*(1/(1+Inputs!$B$6))*G11 -> 182638.81 | H10: =MIN(MAX(C10*(1+Inputs!$B$32),0),1) -> 0.0052656789 | I10: =E10+(1-H10)*D10*(1/(1+Inputs!$B$6))+(1-H10)*(1/(1+Inputs!$B$6))*I11 -> 193363.01 | J10: =E10*(1+Inputs!$B$36) -> 111.42537 | K10: =J10+(1-C10)*D10*(1/(1+Inputs!$B$6))+(1-C10)*(1/(1+Inputs!$B$6))*K11 -> 182866.19 | L10: =(1-C10)*D10*(1/(1+Inputs!$B$6))+(1-C10)*(1/(1+Inputs!$B$6))*L11 -> 180364.98 | M10: =E10+(1-C10)*(1/(1+Inputs!$B$6))*M11 -> 2273.8268 | N10: =F10*G10 -> 53703562 | O10: =F10*MAX(I10-G10,0) -> 3153370.2 | P10: =F10*MAX(K10-G10,0) -> 66860.159 | Q10: =F10*L10 -> 53034961 | R10: =F10*M10 -> 668601.59
A11: 5 | B11: =Inputs!$B$25+A11 -> 70 | C11: =MIN(Inputs!$B$28*(1-EXP(-(Inputs!$B$8+Inputs!$B$9*Inputs!$B$10^B11))),1) -> 0.0073739844 | D11: =Inputs!$B$26 -> 12000 | E11: =Inputs!$B$27*(1+Inputs!$B$19)^A11 -> 104.33467 | F11: =F10*(1-C10) -> 292.10703 | G11: =E11+(1-C11)*D11*(1/(1+Inputs!$B$6))+(1-C11)*(1/(1+Inputs!$B$6))*G12 -> 177259.36 | H11: =MIN(MAX(C11*(1+Inputs!$B$32),0),1) -> 0.0058991875 | I11: =E11+(1-H11)*D11*(1/(1+Inputs!$B$6))+(1-H11)*(1/(1+Inputs!$B$6))*I12 -> 188113.3 | J11: =E11*(1+Inputs!$B$36) -> 114.76813 | K11: =J11+(1-C11)*D11*(1/(1+Inputs!$B$6))+(1-C11)*(1/(1+Inputs!$B$6))*K12 -> 177484.61 | L11: =(1-C11)*D11*(1/(1+Inputs!$B$6))+(1-C11)*(1/(1+Inputs!$B$6))*L12 -> 175006.83 | M11: =E11+(1-C11)*(1/(1+Inputs!$B$6))*M12 -> 2252.5333 | N11: =F11*G11 -> 51778706 | O11: =F11*MAX(I11-G11,0) -> 3170510.8 | P11: =F11*MAX(K11-G11,0) -> 65798.082 | Q11: =F11*L11 -> 51120725 | R11: =F11*M11 -> 657980.82
A12: 6 | B12: =Inputs!$B$25+A12 -> 71 | C12: =MIN(Inputs!$B$28*(1-EXP(-(Inputs!$B$8+Inputs!$B$9*Inputs!$B$10^B12))),1) -> 0.0082630571 | D12: =Inputs!$B$26 -> 12000 | E12: =Inputs!$B$27*(1+Inputs!$B$19)^A12 -> 107.46471 | F12: =F11*(1-C11) -> 289.95304 | G12: =E12+(1-C12)*D12*(1/(1+Inputs!$B$6))+(1-C12)*(1/(1+Inputs!$B$6))*G13 -> 171825.2 | H12: =MIN(MAX(C12*(1+Inputs!$B$32),0),1) -> 0.0066104457 | I12: =E12+(1-H12)*D12*(1/(1+Inputs!$B$6))+(1-H12)*(1/(1+Inputs!$B$6))*I13 -> 182798.38 | J12: =E12*(1+Inputs!$B$36) -> 118.21118 | K12: =J12+(1-C12)*D12*(1/(1+Inputs!$B$6))+(1-C12)*(1/(1+Inputs!$B$6))*K13 -> 172048.11 | L12: =(1-C12)*D12*(1/(1+Inputs!$B$6))+(1-C12)*(1/(1+Inputs!$B$6))*L13 -> 169596.12 | M12: =E12+(1-C12)*(1/(1+Inputs!$B$6))*M13 -> 2229.0818 | N12: =F12*G12 -> 49821240 | O12: =F12*MAX(I12-G12,0) -> 3181707.2 | P12: =F12*MAX(K12-G12,0) -> 64632.905 | Q12: =F12*L12 -> 49174911 | R12: =F12*M12 -> 646329.05
A13: 7 | B13: =Inputs!$B$25+A13 -> 72 | C13: =MIN(Inputs!$B$28*(1-EXP(-(Inputs!$B$8+Inputs!$B$9*Inputs!$B$10^B13))),1) -> 0.0092611044 | D13: =Inputs!$B$26 -> 12000 | E13: =Inputs!$B$27*(1+Inputs!$B$19)^A13 -> 110.68865 | F13: =F12*(1-C12) -> 287.55714 | G13: =E13+(1-C13)*D13*(1/(1+Inputs!$B$6))+(1-C13)*(1/(1+Inputs!$B$6))*G14 -> 166342.93 | H13: =MIN(MAX(C13*(1+Inputs!$B$32),0),1) -> 0.0074088835 | I13: =E13+(1-H13)*D13*(1/(1+Inputs!$B$6))+(1-H13)*(1/(1+Inputs!$B$6))*I14 -> 177423.82 | J13: =E13*(1+Inputs!$B$36) -> 121.75751 | K13: =J13+(1-C13)*D13*(1/(1+Inputs!$B$6))+(1-C13)*(1/(1+Inputs!$B$6))*K14 -> 166563.27 | L13: =(1-C13)*D13*(1/(1+Inputs!$B$6))+(1-C13)*(1/(1+Inputs!$B$6))*L14 -> 164139.45 | M13: =E13+(1-C13)*(1/(1+Inputs!$B$6))*M14 -> 2203.473 | N13: =F13*G13 -> 47833097 | O13: =F13*MAX(I13-G13,0) -> 3186390.4 | P13: =F13*MAX(K13-G13,0) -> 63362.441 | Q13: =F13*L13 -> 47199472 | R13: =F13*M13 -> 633624.41
A14: 8 | B14: =Inputs!$B$25+A14 -> 73 | C14: =MIN(Inputs!$B$28*(1-EXP(-(Inputs!$B$8+Inputs!$B$9*Inputs!$B$10^B14))),1) -> 0.010381307 | D14: =Inputs!$B$26 -> 12000 | E14: =Inputs!$B$27*(1+Inputs!$B$19)^A14 -> 114.00931 | F14: =F13*(1-C13) -> 284.89405 | G14: =E14+(1-C14)*D14*(1/(1+Inputs!$B$6))+(1-C14)*(1/(1+Inputs!$B$6))*G15 -> 160819.71 | H14: =MIN(MAX(C14*(1+Inputs!$B$32),0),1) -> 0.0083050453 | I14: =E14+(1-H14)*D14*(1/(1+Inputs!$B$6))+(1-H14)*(1/(1+Inputs!$B$6))*I15 -> 171995.73 | J14: =E14*(1+Inputs!$B$36) -> 125.41024 | K14: =J14+(1-C14)*D14*(1/(1+Inputs!$B$6))+(1-C14)*(1/(1+Inputs!$B$6))*K15 -> 161037.28 | L14: =(1-C14)*D14*(1/(1+Inputs!$B$6))+(1-C14)*(1/(1+Inputs!$B$6))*L15 -> 158643.99 | M14: =E14+(1-C14)*(1/(1+Inputs!$B$6))*M15 -> 2175.7175 | N14: =F14*G14 -> 45816577 | O14: =F14*MAX(I14-G14,0) -> 3183982.4 | P14: =F14*MAX(K14-G14,0) -> 61984.895 | Q14: =F14*L14 -> 45196728 | R14: =F14*M14 -> 619848.95
A15: 9 | B15: =Inputs!$B$25+A15 -> 74 | C15: =MIN(Inputs!$B$28*(1-EXP(-(Inputs!$B$8+Inputs!$B$9*Inputs!$B$10^B15))),1) -> 0.011638392 | D15: =Inputs!$B$26 -> 12000 | E15: =Inputs!$B$27*(1+Inputs!$B$19)^A15 -> 117.42959 | F15: =F14*(1-C14) -> 281.93647 | G15: =E15+(1-C15)*D15*(1/(1+Inputs!$B$6))+(1-C15)*(1/(1+Inputs!$B$6))*G16 -> 155263.28 | H15: =MIN(MAX(C15*(1+Inputs!$B$32),0),1) -> 0.0093107134 | I15: =E15+(1-H15)*D15*(1/(1+Inputs!$B$6))+(1-H15)*(1/(1+Inputs!$B$6))*I16 -> 166520.79 | J15: =E15*(1+Inputs!$B$36) -> 129.17255 | K15: =J15+(1-C15)*D15*(1/(1+Inputs!$B$6))+(1-C15)*(1/(1+Inputs!$B$6))*K16 -> 155477.86 | L15: =(1-C15)*D15*(1/(1+Inputs!$B$6))+(1-C15)*(1/(1+Inputs!$B$6))*L16 -> 153117.44 | M15: =E15+(1-C15)*(1/(1+Inputs!$B$6))*M16 -> 2145.836 | N15: =F15*G15 -> 43774381 | O15: =F15*MAX(I15-G15,0) -> 3173904.3 | P15: =F15*MAX(K15-G15,0) -> 60498.943 | Q15: =F15*L15 -> 43169392 | R15: =F15*M15 -> 604989.43
A16: 10 | B16: =Inputs!$B$25+A16 -> 75 | C16: =MIN(Inputs!$B$28*(1-EXP(-(Inputs!$B$8+Inputs!$B$9*Inputs!$B$10^B16))),1) -> 0.013048805 | D16: =Inputs!$B$26 -> 12000 | E16: =Inputs!$B$27*(1+Inputs!$B$19)^A16 -> 120.95247 | F16: =F15*(1-C15) -> 278.65519 | G16: =E16+(1-C16)*D16*(1/(1+Inputs!$B$6))+(1-C16)*(1/(1+Inputs!$B$6))*G17 -> 149681.94 | H16: =MIN(MAX(C16*(1+Inputs!$B$32),0),1) -> 0.010439044 | I16: =E16+(1-H16)*D16*(1/(1+Inputs!$B$6))+(1-H16)*(1/(1+Inputs!$B$6))*I17 -> 161006.28 | J16: =E16*(1+Inputs!$B$36) -> 133.04772 | K16: =J16+(1-C16)*D16*(1/(1+Inputs!$B$6))+(1-C16)*(1/(1+Inputs!$B$6))*K17 -> 149893.33 | L16: =(1-C16)*D16*(1/(1+Inputs!$B$6))+(1-C16)*(1/(1+Inputs!$B$6))*L17 -> 147568.08 | M16: =E16+(1-C16)*(1/(1+Inputs!$B$6))*M17 -> 2113.8605 | N16: =F16*G16 -> 41709650 | O16: =F16*MAX(I16-G16,0) -> 3155584.7 | P16: =F16*MAX(K16-G16,0) -> 58903.82 | Q16: =F16*L16 -> 41120611 | R16: =F16*M16 -> 589038.2
A17: 11 | B17: =Inputs!$B$25+A17 -> 76 | C17: =MIN(Inputs!$B$28*(1-EXP(-(Inputs!$B$8+Inputs!$B$9*Inputs!$B$10^B17))),1) -> 0.014630894 | D17: =Inputs!$B$26 -> 12000 | E17: =Inputs!$B$27*(1+Inputs!$B$19)^A17 -> 124.58105 | F17: =F16*(1-C16) -> 275.01907 | G17: =E17+(1-C17)*D17*(1/(1+Inputs!$B$6))+(1-C17)*(1/(1+Inputs!$B$6))*G18 -> 144084.54 | H17: =MIN(MAX(C17*(1+Inputs!$B$32),0),1) -> 0.011704715 | I17: =E17+(1-H17)*D17*(1/(1+Inputs!$B$6))+(1-H17)*(1/(1+Inputs!$B$6))*I18 -> 155460.01 | J17: =E17*(1+Inputs!$B$36) -> 137.03915 | K17: =J17+(1-C17)*D17*(1/(1+Inputs!$B$6))+(1-C17)*(1/(1+Inputs!$B$6))*K18 -> 144292.52 | L17: =(1-C17)*D17*(1/(1+Inputs!$B$6))+(1-C17)*(1/(1+Inputs!$B$6))*L18 -> 142004.7 | M17: =E17+(1-C17)*(1/(1+Inputs!$B$6))*M18 -> 2079.8346 | N17: =F17*G17 -> 39625995 | O17: =F17*MAX(I17-G17,0) -> 3128471.4 | P17: =F17*MAX(K17-G17,0) -> 57199.419 | Q17: =F17*L17 -> 39054001 | R17: =F17*M17 -> 571994.19
A18: 12 | B18: =Inputs!$B$25+A18 -> 77 | C18: =MIN(Inputs!$B$28*(1-EXP(-(Inputs!$B$8+Inputs!$B$9*Inputs!$B$10^B18))),1) -> 0.016405109 | D18: =Inputs!$B$26 -> 12000 | E18: =Inputs!$B$27*(1+Inputs!$B$19)^A18 -> 128.31848 | F18: =F17*(1-C17) -> 270.99529 | G18: =E18+(1-C18)*D18*(1/(1+Inputs!$B$6))+(1-C18)*(1/(1+Inputs!$B$6))*G19 -> 138480.42 | H18: =MIN(MAX(C18*(1+Inputs!$B$32),0),1) -> 0.013124087 | I18: =E18+(1-H18)*D18*(1/(1+Inputs!$B$6))+(1-H18)*(1/(1+Inputs!$B$6))*I19 -> 149890.37 | J18: =E18*(1+Inputs!$B$36) -> 141.15033 | K18: =J18+(1-C18)*D18*(1/(1+Inputs!$B$6))+(1-C18)*(1/(1+Inputs!$B$6))*K19 -> 138684.8 | L18: =(1-C18)*D18*(1/(1+Inputs!$B$6))+(1-C18)*(1/(1+Inputs!$B$6))*L19 -> 136436.6 | M18: =E18+(1-C18)*(1/(1+Inputs!$B$6))*M19 -> 2043.814 | N18: =F18*G18 -> 37527541 | O18: =F18*MAX(I18-G18,0) -> 3092043.5 | P18: =F18*MAX(K18-G18,0) -> 55386.398 | Q18: =F18*L18 -> 36973677 | R18: =F18*M18 -> 553863.98
... A50: 44 | B50: =Inputs!$B$25+A50 -> 109 | C50: =MIN(Inputs!$B$28*(1-EXP(-(Inputs!$B$8+Inputs!$B$9*Inputs!$B$10^B50))),1) -> 0.45187531 | D50: =Inputs!$B$26 -> 12000 | E50: =Inputs!$B$27*(1+Inputs!$B$19)^A50 -> 330.4307 | F50: =F49*(1-C49) -> 1.6172029 | G50: =E50+(1-C50)*D50*(1/(1+Inputs!$B$6))+(1-C50)*(1/(1+Inputs!$B$6))*G51 -> 6716.3495 | H50: =MIN(MAX(C50*(1+Inputs!$B$32),0),1) -> 0.36150024 | I50: =E50+(1-H50)*D50*(1/(1+Inputs!$B$6))+(1-H50)*(1/(1+Inputs!$B$6))*I51 -> 7769.2628 | J50: =E50*(1+Inputs!$B$36) -> 363.47378 | K50: =J50+(1-C50)*D50*(1/(1+Inputs!$B$6))+(1-C50)*(1/(1+Inputs!$B$6))*K51 -> 6749.3925 | L50: =(1-C50)*D50*(1/(1+Inputs!$B$6))+(1-C50)*(1/(1+Inputs!$B$6))*L51 -> 6385.9188 | M50: =E50+(1-C50)*(1/(1+Inputs!$B$6))*M51 -> 330.4307 | N50: =F50*G50 -> 10861.7 | O50: =F50*MAX(I50-G50,0) -> 1702.7745 | P50: =F50*MAX(K50-G50,0) -> 53.437348 | Q50: =F50*L50 -> 10327.326 | R50: =F50*M50 -> 534.37348
A51: end | G51: 0 | I51: 0 | K51: 0 | L51: 0 | M51: 0

Sheet Capital
A1: Capital each year: by risk, diversified, standalone by group, and Euler allocation to groups
A2: Diversified capital = √(Σi Σj ρij Ci Cj) across both groups. Standalone = each group on its own. Euler: risk i's share = Ci × (Σj ρij Cj) ÷ total.
A5: t | B5: Mortality (term) | C5: Longevity (annuity) | D5: Lapse (term) | E5: Expense (term) | F5: Expense (annuity) | G5: Expense (total) | H5: Σj ρ(mort,j)·Cj | I5: Σj ρ(long,j)·Cj | J5: Σj ρ(lapse,j)·Cj | K5: Σj ρ(exp,j)·Cj | L5: Diversified capital (both groups) | M5: Standalone capital: term | N5: Standalone capital: annuity | O5: Sum of standalone | P5: Diversification benefit | Q5: Euler share: mortality | R5: Euler share: longevity | S5: Euler share: lapse | T5: Euler share: expense | U5: Allocated capital: term | V5: Allocated capital: annuity | W5: Check: allocations − total | X5: Proportional allocation: term | Y5: Proportional allocation: annuity
A6: 0 | B6: =Term!U6 -> 3055572.5 | C6: =Annuity!O6 -> 3036146.4 | D6: =Term!V6 -> 661794.1 | E6: =Term!W6 -> 764711.77 | F6: =Annuity!P6 -> 70131.167 | G6: =E6+F6 -> 834842.94 | H6: =Inputs!$B$40*B6+Inputs!$C$40*C6+Inputs!$D$40*D6+Inputs!$E$40*G6 -> 2505246.6 | I6: =Inputs!$B$41*B6+Inputs!$C$41*C6+Inputs!$D$41*D6+Inputs!$E$41*G6 -> 2646412.5 | J6: =Inputs!$B$42*B6+Inputs!$C$42*C6+Inputs!$D$42*D6+Inputs!$E$42*G6 -> 1838252.2 | K6: =Inputs!$B$43*B6+Inputs!$C$43*C6+Inputs!$D$43*D6+Inputs!$E$43*G6 -> 2688669.7 | L6: =SQRT(MAX(B6*H6+C6*I6+D6*J6+G6*K6,0)) -> 4376187.8 | M6: =SQRT(MAX(B6^2+D6^2+E6^2+2*Inputs!$D$40*B6*D6+2*Inputs!$E$40*B6*E6+2*Inputs!$E$42*D6*E6,0)) -> 3468959 | N6: =SQRT(MAX(C6^2+F6^2+2*Inputs!$E$41*C6*F6,0)) -> 3054434 | O6: =M6+N6 -> 6523393 | P6: =IF(O6=0,0,1-L6/O6) -> 0.32915466 | Q6: =IF(L6=0,0,B6*H6/L6) -> 1749230.8 | R6: =IF(L6=0,0,C6*I6/L6) -> 1836049.1 | S6: =IF(L6=0,0,D6*J6/L6) -> 277991.83 | T6: =IF(L6=0,0,G6*K6/L6) -> 512916.04 | U6: =Q6+S6+IF(G6=0,0,T6*E6/G6) -> 2497051.1 | V6: =R6+IF(G6=0,0,T6*F6/G6) -> 1879136.7 | W6: =U6+V6-L6 -> 0 | X6: =IF(O6=0,0,L6*M6/O6) -> 2327135 | Y6: =IF(O6=0,0,L6*N6/O6) -> 2049052.8
A7: 1 | B7: =Term!U7 -> 2993750.1 | C7: =Annuity!O7 -> 3071728.5 | D7: =Term!V7 -> 405370.43 | E7: =Term!W7 -> 725853.13 | F7: =Annuity!P7 -> 69454.102 | G7: =E7+F7 -> 795307.23 | H7: =Inputs!$B$40*B7+Inputs!$C$40*C7+Inputs!$D$40*D7+Inputs!$E$40*G7 -> 2424644.8 | I7: =Inputs!$B$41*B7+Inputs!$C$41*C7+Inputs!$D$41*D7+Inputs!$E$41*G7 -> 2623460.4 | J7: =Inputs!$B$42*B7+Inputs!$C$42*C7+Inputs!$D$42*D7+Inputs!$E$42*G7 -> 1570956.2 | K7: =Inputs!$B$43*B7+Inputs!$C$43*C7+Inputs!$D$43*D7+Inputs!$E$43*G7 -> 2514362.1 | L7: =SQRT(MAX(B7*H7+C7*I7+D7*J7+G7*K7,0)) -> 4237198.1 | M7: =SQRT(MAX(B7^2+D7^2+E7^2+2*Inputs!$D$40*B7*D7+2*Inputs!$E$40*B7*E7+2*Inputs!$E$42*D7*E7,0)) -> 3321818.5 | N7: =SQRT(MAX(C7^2+F7^2+2*Inputs!$E$41*C7*F7,0)) -> 3089823.9 | O7: =M7+N7 -> 6411642.4 | P7: =IF(O7=0,0,1-L7/O7) -> 0.33913998 | Q7: =IF(L7=0,0,B7*H7/L7) -> 1713108.6 | R7: =IF(L7=0,0,C7*I7/L7) -> 1901860.1 | S7: =IF(L7=0,0,D7*J7/L7) -> 150292.52 | T7: =IF(L7=0,0,G7*K7/L7) -> 471936.95 | U7: =Q7+S7+IF(G7=0,0,T7*E7/G7) -> 2294123.8 | V7: =R7+IF(G7=0,0,T7*F7/G7) -> 1943074.3 | W7: =U7+V7-L7 -> 0 | X7: =IF(O7=0,0,L7*M7/O7) -> 2195257 | Y7: =IF(O7=0,0,L7*N7/O7) -> 2041941.1
A8: 2 | B8: =Term!U8 -> 2927673.4 | C8: =Annuity!O8 -> 3103455.3 | D8: =Term!V8 -> 186670.21 | E8: =Term!W8 -> 687188.24 | F8: =Annuity!P8 -> 68685.302 | G8: =E8+F8 -> 755873.54 | H8: =Inputs!$B$40*B8+Inputs!$C$40*C8+Inputs!$D$40*D8+Inputs!$E$40*G8 -> 2340778 | I8: =Inputs!$B$41*B8+Inputs!$C$41*C8+Inputs!$D$41*D8+Inputs!$E$41*G8 -> 2607172.9 | J8: =Inputs!$B$42*B8+Inputs!$C$42*C8+Inputs!$D$42*D8+Inputs!$E$42*G8 -> 1340470.8 | K8: =Inputs!$B$43*B8+Inputs!$C$43*C8+Inputs!$D$43*D8+Inputs!$E$43*G8 -> 2356990.8 | L8: =SQRT(MAX(B8*H8+C8*I8+D8*J8+G8*K8,0)) -> 4120205.2 | M8: =SQRT(MAX(B8^2+D8^2+E8^2+2*Inputs!$D$40*B8*D8+2*Inputs!$E$40*B8*E8+2*Inputs!$E$42*D8*E8,0)) -> 3195708.7 | N8: =SQRT(MAX(C8^2+F8^2+2*Inputs!$E$41*C8*F8,0)) -> 3121335.2 | O8: =M8+N8 -> 6317043.9 | P8: =IF(O8=0,0,1-L8/O8) -> 0.34776372 | Q8: =IF(L8=0,0,B8*H8/L8) -> 1663274.8 | R8: =IF(L8=0,0,C8*I8/L8) -> 1963796.5 | S8: =IF(L8=0,0,D8*J8/L8) -> 60731.431 | T8: =IF(L8=0,0,G8*K8/L8) -> 432402.49 | U8: =Q8+S8+IF(G8=0,0,T8*E8/G8) -> 2117116.8 | V8: =R8+IF(G8=0,0,T8*F8/G8) -> 2003088.4 | W8: =U8+V8-L8 -> 0 | X8: =IF(O8=0,0,L8*M8/O8) -> 2084357.2 | Y8: =IF(O8=0,0,L8*N8/O8) -> 2035848.1
A9: 3 | B9: =Term!U9 -> 2856664 | C9: =Annuity!O9 -> 3130840 | D9: =Term!V9 -> 207326.63 | E9: =Term!W9 -> 648695.13 | F9: =Annuity!P9 -> 67821.644 | G9: =E9+F9 -> 716516.78 | H9: =Inputs!$B$40*B9+Inputs!$C$40*C9+Inputs!$D$40*D9+Inputs!$E$40*G9 -> 2253083.2 | I9: =Inputs!$B$41*B9+Inputs!$C$41*C9+Inputs!$D$41*D9+Inputs!$E$41*G9 -> 2647634.8 | J9: =Inputs!$B$42*B9+Inputs!$C$42*C9+Inputs!$D$42*D9+Inputs!$E$42*G9 -> 1348295 | K9: =Inputs!$B$43*B9+Inputs!$C$43*C9+Inputs!$D$43*D9+Inputs!$E$43*G9 -> 2317056.1 | L9: =SQRT(MAX(B9*H9+C9*I9+D9*J9+G9*K9,0)) -> 4082324 | M9: =SQRT(MAX(B9^2+D9^2+E9^2+2*Inputs!$D$40*B9*D9+2*Inputs!$E$40*B9*E9+2*Inputs!$E$42*D9*E9,0)) -> 3112131.5 | N9: =SQRT(MAX(C9^2+F9^2+2*Inputs!$E$41*C9*F9,0)) -> 3148480.3 | O9: =M9+N9 -> 6260611.8 | P9: =IF(O9=0,0,1-L9/O9) -> 0.34793529 | Q9: =IF(L9=0,0,B9*H9/L9) -> 1576626.8 | R9: =IF(L9=0,0,C9*I9/L9) -> 2030539.7 | S9: =IF(L9=0,0,D9*J9/L9) -> 68475.078 | T9: =IF(L9=0,0,G9*K9/L9) -> 406682.46 | U9: =Q9+S9+IF(G9=0,0,T9*E9/G9) -> 2013290 | V9: =R9+IF(G9=0,0,T9*F9/G9) -> 2069034.1 | W9: =U9+V9-L9 -> 0 | X9: =IF(O9=0,0,L9*M9/O9) -> 2029311.1 | Y9: =IF(O9=0,0,L9*N9/O9) -> 2053012.9
A10: 4 | B10: =Term!U10 -> 2780006.6 | C10: =Annuity!O10 -> 3153370.2 | D10: =Term!V10 -> 349307.98 | E10: =Term!W10 -> 610351.96 | F10: =Annuity!P10 -> 66860.159 | G10: =E10+F10 -> 677212.12 | H10: =Inputs!$B$40*B10+Inputs!$C$40*C10+Inputs!$D$40*D10+Inputs!$E$40*G10 -> 2160967.1 | I10: =Inputs!$B$41*B10+Inputs!$C$41*C10+Inputs!$D$41*D10+Inputs!$E$41*G10 -> 2714998.5 | J10: =Inputs!$B$42*B10+Inputs!$C$42*C10+Inputs!$D$42*D10+Inputs!$E$42*G10 -> 1476256.6 | K10: =Inputs!$B$43*B10+Inputs!$C$43*C10+Inputs!$D$43*D10+Inputs!$E$43*G10 -> 2335210.3 | L10: =SQRT(MAX(B10*H10+C10*I10+D10*J10+G10*K10,0)) -> 4082401.1 | M10: =SQRT(MAX(B10^2+D10^2+E10^2+2*Inputs!$D$40*B10*D10+2*Inputs!$E$40*B10*E10+2*Inputs!$E$42*D10*E10,0)) -> 3047059.9 | N10: =SQRT(MAX(C10^2+F10^2+2*Inputs!$E$41*C10*F10,0)) -> 3170746.1 | O10: =M10+N10 -> 6217806.1 | P10: =IF(O10=0,0,1-L10/O10) -> 0.34343383 | Q10: =IF(L10=0,0,B10*H10/L10) -> 1471561.1 | R10: =IF(L10=0,0,C10*I10/L10) -> 2097147 | S10: =IF(L10=0,0,D10*J10/L10) -> 126314.93 | T10: =IF(L10=0,0,G10*K10/L10) -> 387378.08 | U10: =Q10+S10+IF(G10=0,0,T10*E10/G10) -> 1947008.8 | V10: =R10+IF(G10=0,0,T10*F10/G10) -> 2135392.3 | W10: =U10+V10-L10 -> 0 | X10: =IF(O10=0,0,L10*M10/O10) -> 2000596.5 | Y10: =IF(O10=0,0,L10*N10/O10) -> 2081804.7
A11: 5 | B11: =Term!U11 -> 2696946.5 | C11: =Annuity!O11 -> 3170510.8 | D11: =Term!V11 -> 453111.87 | E11: =Term!W11 -> 572136.99 | F11: =Annuity!P11 -> 65798.082 | G11: =E11+F11 -> 637935.07 | H11: =Inputs!$B$40*B11+Inputs!$C$40*C11+Inputs!$D$40*D11+Inputs!$E$40*G11 -> 2063802.6 | I11: =Inputs!$B$41*B11+Inputs!$C$41*C11+Inputs!$D$41*D11+Inputs!$E$41*G11 -> 2769035.9 | J11: =Inputs!$B$42*B11+Inputs!$C$42*C11+Inputs!$D$42*D11+Inputs!$E$42*G11 -> 1564707.1 | K11: =Inputs!$B$43*B11+Inputs!$C$43*C11+Inputs!$D$43*D11+Inputs!$E$43*G11 -> 2331355.3 | L11: =SQRT(MAX(B11*H11+C11*I11+D11*J11+G11*K11,0)) -> 4067119.8 | M11: =SQRT(MAX(B11^2+D11^2+E11^2+2*Inputs!$D$40*B11*D11+2*Inputs!$E$40*B11*E11+2*Inputs!$E$42*D11*E11,0)) -> 2972696.6 | N11: =SQRT(MAX(C11^2+F11^2+2*Inputs!$E$41*C11*F11,0)) -> 3187597 | O11: =M11+N11 -> 6160293.6 | P11: =IF(O11=0,0,1-L11/O11) -> 0.33978474 | Q11: =IF(L11=0,0,B11*H11/L11) -> 1368527.5 | R11: =IF(L11=0,0,C11*I11/L11) -> 2158593.4 | S11: =IF(L11=0,0,D11*J11/L11) -> 174321.73 | T11: =IF(L11=0,0,G11*K11/L11) -> 365677.28 | U11: =Q11+S11+IF(G11=0,0,T11*E11/G11) -> 1870809.7 | V11: =R11+IF(G11=0,0,T11*F11/G11) -> 2196310.2 | W11: =U11+V11-L11 -> 0 | X11: =IF(O11=0,0,L11*M11/O11) -> 1962619.7 | Y11: =IF(O11=0,0,L11*N11/O11) -> 2104500.2
A12: 6 | B12: =Term!U12 -> 2606685.8 | C12: =Annuity!O12 -> 3181707.2 | D12: =Term!V12 -> 522294.69 | E12: =Term!W12 -> 534028.6 | F12: =Annuity!P12 -> 64632.905 | G12: =E12+F12 -> 598661.5 | H12: =Inputs!$B$40*B12+Inputs!$C$40*C12+Inputs!$D$40*D12+Inputs!$E$40*G12 -> 1960924.3 | I12: =Inputs!$B$41*B12+Inputs!$C$41*C12+Inputs!$D$41*D12+Inputs!$E$41*G12 -> 2810274.8 | J12: =Inputs!$B$42*B12+Inputs!$C$42*C12+Inputs!$D$42*D12+Inputs!$E$42*G12 -> 1617052.2 | K12: =Inputs!$B$43*B12+Inputs!$C$43*C12+Inputs!$D$43*D12+Inputs!$E$43*G12 -> 2306907.1 | L12: =SQRT(MAX(B12*H12+C12*I12+D12*J12+G12*K12,0)) -> 4034677.1 | M12: =SQRT(MAX(B12^2+D12^2+E12^2+2*Inputs!$D$40*B12*D12+2*Inputs!$E$40*B12*E12+2*Inputs!$E$42*D12*E12,0)) -> 2885781 | N12: =SQRT(MAX(C12^2+F12^2+2*Inputs!$E$41*C12*F12,0)) -> 3198477.7 | O12: =M12+N12 -> 6084258.7 | P12: =IF(O12=0,0,1-L12/O12) -> 0.33686627 | Q12: =IF(L12=0,0,B12*H12/L12) -> 1266895.3 | R12: =IF(L12=0,0,C12*I12/L12) -> 2216155.4 | S12: =IF(L12=0,0,D12*J12/L12) -> 209329.71 | T12: =IF(L12=0,0,G12*K12/L12) -> 342296.65 | U12: =Q12+S12+IF(G12=0,0,T12*E12/G12) -> 1781566.5 | V12: =R12+IF(G12=0,0,T12*F12/G12) -> 2253110.6 | W12: =U12+V12-L12 -> 0 | X12: =IF(O12=0,0,L12*M12/O12) -> 1913658.7 | Y12: =IF(O12=0,0,L12*N12/O12) -> 2121018.5
A13: 7 | B13: =Term!U13 -> 2508379.8 | C13: =Annuity!O13 -> 3186390.4 | D13: =Term!V13 -> 560435.22 | E13: =Term!W13 -> 496005.31 | F13: =Annuity!P13 -> 63362.441 | G13: =E13+F13 -> 559367.75 | H13: =Inputs!$B$40*B13+Inputs!$C$40*C13+Inputs!$D$40*D13+Inputs!$E$40*G13 -> 1851624.1 | I13: =Inputs!$B$41*B13+Inputs!$C$41*C13+Inputs!$D$41*D13+Inputs!$E$41*G13 -> 2839246.2 | J13: =Inputs!$B$42*B13+Inputs!$C$42*C13+Inputs!$D$42*D13+Inputs!$E$42*G13 -> 1636716.7 | K13: =Inputs!$B$43*B13+Inputs!$C$43*C13+Inputs!$D$43*D13+Inputs!$E$43*G13 -> 2263277.9 | L13: =SQRT(MAX(B13*H13+C13*I13+D13*J13+G13*K13,0)) -> 3984319.5 | M13: =SQRT(MAX(B13^2+D13^2+E13^2+2*Inputs!$D$40*B13*D13+2*Inputs!$E$40*B13*E13+2*Inputs!$E$42*D13*E13,0)) -> 2784266.8 | N13: =SQRT(MAX(C13^2+F13^2+2*Inputs!$E$41*C13*F13,0)) -> 3202818.6 | O13: =M13+N13 -> 5987085.4 | P13: =IF(O13=0,0,1-L13/O13) -> 0.33451435 | Q13: =IF(L13=0,0,B13*H13/L13) -> 1165713.9 | R13: =IF(L13=0,0,C13*I13/L13) -> 2270637.9 | S13: =IF(L13=0,0,D13*J13/L13) -> 230220.92 | T13: =IF(L13=0,0,G13*K13/L13) -> 317746.78 | U13: =Q13+S13+IF(G13=0,0,T13*E13/G13) -> 1677688.8 | V13: =R13+IF(G13=0,0,T13*F13/G13) -> 2306630.7 | W13: =U13+V13-L13 -> 0 | X13: =IF(O13=0,0,L13*M13/O13) -> 1852889.6 | Y13: =IF(O13=0,0,L13*N13/O13) -> 2131429.9
A14: 8 | B14: =Term!U14 -> 2401133.2 | C14: =Annuity!O14 -> 3183982.4 | D14: =Term!V14 -> 571149.99 | E14: =Term!W14 -> 458045.79 | F14: =Annuity!P14 -> 61984.895 | G14: =E14+F14 -> 520030.68 | H14: =Inputs!$B$40*B14+Inputs!$C$40*C14+Inputs!$D$40*D14+Inputs!$E$40*G14 -> 1735145.3 | I14: =Inputs!$B$41*B14+Inputs!$C$41*C14+Inputs!$D$41*D14+Inputs!$E$41*G14 -> 2856494.3 | J14: =Inputs!$B$42*B14+Inputs!$C$42*C14+Inputs!$D$42*D14+Inputs!$E$42*G14 -> 1627160.9 | K14: =Inputs!$B$43*B14+Inputs!$C$43*C14+Inputs!$D$43*D14+Inputs!$E$43*G14 -> 2201884.6 | L14: =SQRT(MAX(B14*H14+C14*I14+D14*J14+G14*K14,0)) -> 3916087.7 | M14: =SQRT(MAX(B14^2+D14^2+E14^2+2*Inputs!$D$40*B14*D14+2*Inputs!$E$40*B14*E14+2*Inputs!$E$42*D14*E14,0)) -> 2667018.2 | N14: =SQRT(MAX(C14^2+F14^2+2*Inputs!$E$41*C14*F14,0)) -> 3200041.5 | O14: =M14+N14 -> 5867059.7 | P14: =IF(O14=0,0,1-L14/O14) -> 0.33252977 | Q14: =IF(L14=0,0,B14*H14/L14) -> 1063897.2 | R14: =IF(L14=0,0,C14*I14/L14) -> 2322478 | S14: =IF(L14=0,0,D14*J14/L14) -> 237316.69 | T14: =IF(L14=0,0,G14*K14/L14) -> 292395.79 | U14: =Q14+S14+IF(G14=0,0,T14*E14/G14) -> 1558757.7 | V14: =R14+IF(G14=0,0,T14*F14/G14) -> 2357330 | W14: =U14+V14-L14 -> 0 | X14: =IF(O14=0,0,L14*M14/O14) -> 1780155.3 | Y14: =IF(O14=0,0,L14*N14/O14) -> 2135932.4
A15: 9 | B15: =Term!U15 -> 2283996 | C15: =Annuity!O15 -> 3173904.3 | D15: =Term!V15 -> 558108.97 | E15: =Term!W15 -> 420128.84 | F15: =Annuity!P15 -> 60498.943 | G15: =E15+F15 -> 480627.79 | H15: =Inputs!$B$40*B15+Inputs!$C$40*C15+Inputs!$D$40*D15+Inputs!$E$40*G15 -> 1610676.8 | I15: =Inputs!$B$41*B15+Inputs!$C$41*C15+Inputs!$D$41*D15+Inputs!$E$41*G15 -> 2862589.5 | J15: =Inputs!$B$42*B15+Inputs!$C$42*C15+Inputs!$D$42*D15+Inputs!$E$42*G15 -> 1591898.9 | K15: =Inputs!$B$43*B15+Inputs!$C$43*C15+Inputs!$D$43*D15+Inputs!$E$43*G15 -> 2124157.3 | L15: =SQRT(MAX(B15*H15+C15*I15+D15*J15+G15*K15,0)) -> 3830632.6 | M15: =SQRT(MAX(B15^2+D15^2+E15^2+2*Inputs!$D$40*B15*D15+2*Inputs!$E$40*B15*E15+2*Inputs!$E$42*D15*E15,0)) -> 2533553.9 | N15: =SQRT(MAX(C15^2+F15^2+2*Inputs!$E$41*C15*F15,0)) -> 3189566.9 | O15: =M15+N15 -> 5723120.8 | P15: =IF(O15=0,0,1-L15/O15) -> 0.33067417 | Q15: =IF(L15=0,0,B15*H15/L15) -> 960358.19 | R15: =IF(L15=0,0,C15*I15/L15) -> 2371823.6 | S15: =IF(L15=0,0,D15*J15/L15) -> 231933.77 | T15: =IF(L15=0,0,G15*K15/L15) -> 266517.08 | U15: =Q15+S15+IF(G15=0,0,T15*E15/G15) -> 1425261.2 | V15: =R15+IF(G15=0,0,T15*F15/G15) -> 2405371.4 | W15: =U15+V15-L15 -> 0 | X15: =IF(O15=0,0,L15*M15/O15) -> 1695773.1 | Y15: =IF(O15=0,0,L15*N15/O15) -> 2134859.6
A16: 10 | B16: =Term!U16 -> 2155958.6 | C16: =Annuity!O16 -> 3155584.7 | D16: =Term!V16 -> 525051.54 | E16: =Term!W16 -> 382233.45 | F16: =Annuity!P16 -> 58903.82 | G16: =E16+F16 -> 441137.27 | H16: =Inputs!$B$40*B16+Inputs!$C$40*C16+Inputs!$D$40*D16+Inputs!$E$40*G16 -> 1477346.8 | I16: =Inputs!$B$41*B16+Inputs!$C$41*C16+Inputs!$D$41*D16+Inputs!$E$41*G16 -> 2858142.3 | J16: =Inputs!$B$42*B16+Inputs!$C$42*C16+Inputs!$D$42*D16+Inputs!$E$42*G16 -> 1534516.4 | K16: =Inputs!$B$43*B16+Inputs!$C$43*C16+Inputs!$D$43*D16+Inputs!$E$43*G16 -> 2031548.9 | L16: =SQRT(MAX(B16*H16+C16*I16+D16*J16+G16*K16,0)) -> 3729088.5 | M16: =SQRT(MAX(B16^2+D16^2+E16^2+2*Inputs!$D$40*B16*D16+2*Inputs!$E$40*B16*E16+2*Inputs!$E$42*D16*E16,0)) -> 2383835.4 | N16: =SQRT(MAX(C16^2+F16^2+2*Inputs!$E$41*C16*F16,0)) -> 3170823.6 | O16: =M16+N16 -> 5554659 | P16: =IF(O16=0,0,1-L16/O16) -> 0.32865574 | Q16: =IF(L16=0,0,B16*H16/L16) -> 854122.55 | R16: =IF(L16=0,0,C16*I16/L16) -> 2418583 | S16: =IF(L16=0,0,D16*J16/L16) -> 216058.21 | T16: =IF(L16=0,0,G16*K16/L16) -> 240324.67 | U16: =Q16+S16+IF(G16=0,0,T16*E16/G16) -> 1278415.5 | V16: =R16+IF(G16=0,0,T16*F16/G16) -> 2450672.9 | W16: =U16+V16-L16 -> 0 | X16: =IF(O16=0,0,L16*M16/O16) -> 1600374.2 | Y16: =IF(O16=0,0,L16*N16/O16) -> 2128714.3
A17: 11 | B17: =Term!U17 -> 2015947.5 | C17: =Annuity!O17 -> 3128471.4 | D17: =Term!V17 -> 475802.92 | E17: =Term!W17 -> 344338.78 | F17: =Annuity!P17 -> 57199.419 | G17: =E17+F17 -> 401538.2 | H17: =Inputs!$B$40*B17+Inputs!$C$40*C17+Inputs!$D$40*D17+Inputs!$E$40*G17 -> 1334214.2 | I17: =Inputs!$B$41*B17+Inputs!$C$41*C17+Inputs!$D$41*D17+Inputs!$E$41*G17 -> 2843819.8 | J17: =Inputs!$B$42*B17+Inputs!$C$42*C17+Inputs!$D$42*D17+Inputs!$E$42*G17 -> 1458689.9 | K17: =Inputs!$B$43*B17+Inputs!$C$43*C17+Inputs!$D$43*D17+Inputs!$E$43*G17 -> 1925544.4 | L17: =SQRT(MAX(B17*H17+C17*I17+D17*J17+G17*K17,0)) -> 3612996.4 | M17: =SQRT(MAX(B17^2+D17^2+E17^2+2*Inputs!$D$40*B17*D17+2*Inputs!$E$40*B17*E17+2*Inputs!$E$42*D17*E17,0)) -> 2218090.1 | N17: =SQRT(MAX(C17^2+F17^2+2*Inputs!$E$41*C17*F17,0)) -> 3143259.2 | O17: =M17+N17 -> 5361349.3 | P17: =IF(O17=0,0,1-L17/O17) -> 0.32610315 | Q17: =IF(L17=0,0,B17*H17/L17) -> 744452.89 | R17: =IF(L17=0,0,C17*I17/L17) -> 2462446.1 | S17: =IF(L17=0,0,D17*J17/L17) -> 192097.86 | T17: =IF(L17=0,0,G17*K17/L17) -> 213999.55 | U17: =Q17+S17+IF(G17=0,0,T17*E17/G17) -> 1120065.9 | V17: =R17+IF(G17=0,0,T17*F17/G17) -> 2492930.5 | W17: =U17+V17-L17 -> 0 | X17: =IF(O17=0,0,L17*M17/O17) -> 1494763.9 | Y17: =IF(O17=0,0,L17*N17/O17) -> 2118232.5
... A25: 19 | B25: =Term!U25 -> 309891.4 | C25: =Annuity!O25 -> 2546838.4 | D25: =Term!V25 -> 0 | E25: =Term!W25 -> 38784.101 | F25: =Annuity!P25 -> 39926.749 | G25: =E25+F25 -> 78710.85 | H25: =Inputs!$B$40*B25+Inputs!$C$40*C25+Inputs!$D$40*D25+Inputs!$E$40*G25 -> -307140.49 | I25: =Inputs!$B$41*B25+Inputs!$C$41*C25+Inputs!$D$41*D25+Inputs!$E$41*G25 -> 2489043.2 | J25: =Inputs!$B$42*B25+Inputs!$C$42*C25+Inputs!$D$42*D25+Inputs!$E$42*G25 -> 676065.02 | K25: =Inputs!$B$43*B25+Inputs!$C$43*C25+Inputs!$D$43*D25+Inputs!$E$43*G25 -> 792893.3 | L25: =SQRT(MAX(B25*H25+C25*I25+D25*J25+G25*K25,0)) -> 2511258.6 | M25: =SQRT(MAX(B25^2+D25^2+E25^2+2*Inputs!$D$40*B25*D25+2*Inputs!$E$40*B25*E25+2*Inputs!$E$42*D25*E25,0)) -> 321786.13 | N25: =SQRT(MAX(C25^2+F25^2+2*Inputs!$E$41*C25*F25,0)) -> 2557112.3 | O25: =M25+N25 -> 2878898.4 | P25: =IF(O25=0,0,1-L25/O25) -> 0.12770155 | Q25: =IF(L25=0,0,B25*H25/L25) -> -37901.39 | R25: =IF(L25=0,0,C25*I25/L25) -> 2524308.2 | S25: =IF(L25=0,0,D25*J25/L25) -> 0 | T25: =IF(L25=0,0,G25*K25/L25) -> 24851.803 | U25: =Q25+S25+IF(G25=0,0,T25*E25/G25) -> -25655.876 | V25: =R25+IF(G25=0,0,T25*F25/G25) -> 2536914.5 | W25: =U25+V25-L25 -> 0 | X25: =IF(O25=0,0,L25*M25/O25) -> 280693.54 | Y25: =IF(O25=0,0,L25*N25/O25) -> 2230565.1
